Workbook

Sheet 使い方
A1: 現場でんき探偵Pro ― 財務モデル（慎重・標準・好調シナリオ）
A3: ■ このファイルの構成
A4: ・前提条件 … 3シナリオ（慎重／標準／好調）の入力値をすべて集約したシート。青文字のセルが入力値です。
A5: ・慎重ケース／標準ケース／好調ケース … 各シナリオの36ヶ月分の月次モデル。数式で自動計算されるため、
A6: 「前提条件」シートの数値を書き換えると全シートが再計算されます。
A7: ・サマリー比較 … 12ヶ月・24ヶ月・36ヶ月時点の主要指標を3シナリオ横並びで比較。損益分岐月も表示。
A8: ・AI費用比較 … AI機能を限定した場合と多用した場合のAI API費用インパクトを比較。
A10: ■ 色の意味
A11: ・青文字：前提条件シートの入力セル（自由に変更可）
A12: ・黒文字：数式で自動計算されるセル（通常は編集不要）
A13: ・緑文字：他シートを参照している数式
A14: ・黄色の網掛け：特に重要な前提条件（変更した場合は他シートに大きく影響）
... A24: ・出典・根拠は「前提条件」シートの備考欄、およびマーケティングレポート本編（Markdown）をご参照ください。

Sheet 前提条件
A1: 現場でんき探偵Pro ― 前提条件（3シナリオ入力値）
A2: 数値は仮定に基づく試算です。詳細な根拠はマーケティングレポート本編を参照してください。
A4: 項目 | B4: 単位 | C4: 慎重ケース | D4: 標準ケース | E4: 好調ケース | F4: 備考・根拠（仮定／出典）
A5: ■ ユーザー獲得・利用
A6: Month1 新規ダウンロード数 | B6: 人 | C6: 150 | D6: 300 | E6: 500 | F6: 仮定：β非公開テスター経由の口コミ＋公開初月のSNS告知規模から試算
A7: 月次成長率（1〜12ヶ月目） | B7: % | C7: 0.04 | D7: 0.07 | E7: 0.1 | F7: 仮定：無料ASO＋SNS投稿中心。伸び率は個人開発アプリの立ち上がりを参考に保守的に設定
A8: 月次成長率（13〜24ヶ月目） | B8: % | C8: 0.02 | D8: 0.04 | E8: 0.05 | F8: 仮定：新規性の逓減を反映し1年目より鈍化
A9: 月次成長率（25〜36ヶ月目） | B9: % | C9: 0.01 | D9: 0.02 | E9: 0.025 | F9: 仮定：市場成熟に伴いさらに鈍化
A10: ストア閲覧→ダウンロード転換率 | B10: % | C10: 0.25 | D10: 0.3 | E10: 0.35 | F10: 仮定：Google Play一般的なCVR目安（20〜30%）を参考に設定
A11: ダウンロード→アクティブ化率（MAU算入） | B11: % | C11: 0.4 | D11: 0.45 | E11: 0.55 | F11: 仮定：現場業務ツールは「入れたが使わない」離脱が一定数出るため控えめに設定
A12: 無料会員 月次解約率 | B12: % | C12: 0.08 | D12: 0.07 | E12: 0.06 | F12: 仮定：現場が変わる・使わなくなる等によるアンインストール／休眠を想定
A13: 無料→有料 転換率（ランプ到達後の値） | B13: % | C13: 0.03 | D13: 0.05 | E13: 0.08 | F13: 仮定：業務系スマホアプリの無料→有料転換率（一般に2〜10%）を参考に設定
A14: 転換率ランプ期間 | B14: ヶ月 | C14: 6 | D14: 5 | E14: 4 | F14: 仮定：信頼形成・機能拡充により転換率が徐々に目標値へ到達すると想定
A15: 有料会員（個人）月次解約率 | B15: % | C15: 0.05 | D15: 0.04 | E15: 0.03 | F15: 仮定：課金後は業務定着し解約率は無料会員より低いと想定
A16: 個人ARPU（月額・税込） | B16: 円 | C16: 550 | D16: 620 | E16: 700 | F16: 仮定：月額500円/980円プランの混在比率から算出。詳細は本編セクション5参照
A17: ■ 法人契約
A18: 法人契約 開始月 | B18: 月目 | C18: 7 | D18: 5 | E18: 4 | F18: 仮定：個人ユーザー基盤形成後に法人営業を開始
A19: 法人新規契約数/月（開始〜12ヶ月目） | B19: 社 | C19: 0.3 | D19: 1 | E19: 1.8 | F19: 仮定：知人企業・β協力企業からの紹介を想定
A20: 法人新規契約数/月（13〜24ヶ月目） | B20: 社 | C20: 0.5 | D20: 1.6 | E20: 2.8 | F20: 仮定：実績・事例が蓄積し営業効率が向上
A21: 法人新規契約数/月（25〜36ヶ月目） | B21: 社 | C21: 0.8 | D21: 2.2 | E21: 3.8 | F21: 仮定：紹介・展示会経由の引き合い増加を想定
A22: 法人契約 月次解約率 | B22: % | C22: 0.04 | D22: 0.025 | E22: 0.02 | F22: 仮定：個人より解約率は低いが、現場責任者交代等での離脱を想定
A23: 法人平均契約単価（月額/社） | B23: 円 | C23: 2000 | D23: 2600 | E23: 3200 | F23: 仮定：5名・10名プランの混在（1人あたり300〜400円想定）
A24: ■ 費用前提
A25: サーバー・インフラ費（1〜12ヶ月目） | B25: 円/月 | C25: 15000 | D25: 15000 | E25: 18000 | F25: 仮定：GitHub Pages無料枠＋小規模VPS/CDN費用の目安
A26: サーバー・インフラ費（13ヶ月目以降） | B26: 円/月 | C26: 25000 | D26: 30000 | E26: 40000 | F26: 仮定：利用増に伴うインフラ増強（要確認：実際の構成により変動）
A27: Firebase従量費 単価 | B27: 円/MAU/月 | C27: 3 | D27: 3 | E27: 3 | F27: 仮定：Firestore読み書き・認証・Hosting従量課金の概算（要確認：実利用量で変動）
A28: AI API費 単価（限定AI版） | B28: 円/有料会員/月 | C28: 8 | D28: 8 | E28: 8 | F28: 仮定：用語検索など軽量なAI呼び出しに限定した場合の概算
A29: AI API費 単価（拡張AI版・参考比較用） | B29: 円/有料会員/月 | C29: 25 | D29: 25 | E29: 25 | F29: 仮定：AIチャット相談・画像解析等を多用した場合の概算（AI費用比較シート参照）
A30: 決済・ストア手数料率 | B30: % | C30: 0.08 | D30: 0.08 | E30: 0.08 | F30: 仮定：Google Playサブスク手数料10%（2026年6月改定後）と、Web直販時の決済手数料（Stripe目安3.6%等）
A31: 広告・マーケティング費（1〜12ヶ月目） | B31: 円/月 | C31: 30000 | D31: 80000 | E31: 150000 | F31: 仮定：低予算のSNS運用＋一部有料広告
A32: 広告・マーケティング費（13〜24ヶ月目） | B32: 円/月 | C32: 40000 | D32: 100000 | E32: 200000 | F32: 仮定：売上成長に応じた再投資
A33: 広告・マーケティング費（25〜36ヶ月目） | B33: 円/月 | C33: 50000 | D33: 120000 | E33: 250000 | F33: 仮定：ブランド確立後も一定投資を継続
A34: カスタマーサポート費 発動閾値（有料会員数） | B34: 人 | C34: 500 | D34: 500 | E34: 500 | F34: 仮定：この人数を超えたら外部委託または人員追加が必要と想定
A35: カスタマーサポート費（閾値超過後） | B35: 円/月 | C35: 50000 | D35: 50000 | E35: 60000 | F35: 仮定：パートタイム相当の対応工数
A36: 法人営業費 発動閾値（契約社数） | B36: 社 | C36: 10 | D36: 10 | E36: 10 | F36: 仮定：この社数を超えたら営業活動の本格化が必要と想定
... A38: 予備費率（総費用に対する比率） | B38: % | C38: 0.1 | D38: 0.1 | E38: 0.1 | F38: 仮定：想定外費用に備えた一般的なバッファ

Sheet 慎重ケース
A1: 現場でんき探偵Pro ― 慎重ケース（月次モデル・36ヶ月）
A2: 青文字セルなし＝本シートは全セルが数式。入力値は「前提条件」シートで編集してください。
A4: 月 | B4: ストア閲覧数 | C4: 新規DL数 | D4: 累計DL数 | E4: 無料会員数 | F4: 有料会員数(個人) | G4: MAU(月間利用者数) | H4: 当月転換率(無料→有料) | I4: 新規有料転換数 | J4: 個人課金売上(円) | K4: 法人新規契約数 | L4: 法人契約数累計 | M4: 法人売上(円) | N4: 売上合計(円) | O4: サーバー・インフラ費 | P4: Firebase従量費 | Q4: AI API費(限定AI版) | R4: 決済・ストア手数料 | S4: 広告・マーケティング費 | T4: CS費 | U4: 法人営業費 | V4: 予備費 | W4: 費用合計(円) | X4: 月次損益(円) | Y4: 累計損益(円)
A5: 0 | B5: 0 | C5: 0 | D5: 0 | E5: 0 | F5: 0 | G5: 0 | H5: 0 | I5: 0 | J5: 0 | K5: 0 | L5: 0 | M5: 0 | N5: 0 | O5: 0 | P5: 0 | Q5: 0 | R5: 0 | S5: 0 | T5: 0 | U5: 0 | V5: 0 | W5: 0 | X5: 0 | Y5: 0
A6: 1 | B6: =C6/前提条件!$C$10 -> 600 | C6: =前提条件!$C$6 -> 150 | D6: =D5+C6 -> 150 | E6: =MAX(0,E5*(1-前提条件!$C$12)+C6*前提条件!$C$11-I6) -> 60 | F6: =F5*(1-前提条件!$C$15)+I6 -> 0 | G6: =E6+F6 -> 60 | H6: =前提条件!$C$13*MIN(1,$A6/前提条件!$C$14) -> 0.005 | I6: =E5*H6 -> 0 | J6: =F6*前提条件!$C$16 -> 0 | K6: =IF($A6<前提条件!$C$18,0,IF($A6<=12,前提条件!$C$19,IF($A6<=24,前提条件!$C$20,前提条件!$C$21))) -> 0 | L6: =L5*(1-前提条件!$C$22)+K6 -> 0 | M6: =L6*前提条件!$C$23 -> 0 | N6: =J6+M6 -> 0 | O6: =IF($A6<=12,前提条件!$C$25,前提条件!$C$26) -> 15000 | P6: =G6*前提条件!$C$27 -> 180 | Q6: =F6*前提条件!$C$28 -> 0 | R6: =N6*前提条件!$C$30 -> 0 | S6: =IF($A6<=12,前提条件!$C$31,IF($A6<=24,前提条件!$C$32,前提条件!$C$33)) -> 30000 | T6: =IF(F6>=前提条件!$C$34,前提条件!$C$35,0) -> 0 | U6: =IF(L6>=前提条件!$C$36,前提条件!$C$37,0) -> 0 | V6: =(O6+P6+Q6+R6+S6+T6+U6)*前提条件!$C$38 -> 4518 | W6: =O6+P6+Q6+R6+S6+T6+U6+V6 -> 49698 | X6: =N6-W6 -> -49698 | Y6: =Y5+X6 -> -49698
A7: 2 | B7: =C7/前提条件!$C$10 -> 624 | C7: =C6*(1+IF($A7<=12,前提条件!$C$7,IF($A7<=24,前提条件!$C$8,前提条件!$C$9))) -> 156 | D7: =D6+C7 -> 306 | E7: =MAX(0,E6*(1-前提条件!$C$12)+C7*前提条件!$C$11-I7) -> 117 | F7: =F6*(1-前提条件!$C$15)+I7 -> 0.6 | G7: =E7+F7 -> 117.6 | H7: =前提条件!$C$13*MIN(1,$A7/前提条件!$C$14) -> 0.01 | I7: =E6*H7 -> 0.6 | J7: =F7*前提条件!$C$16 -> 330 | K7: =IF($A7<前提条件!$C$18,0,IF($A7<=12,前提条件!$C$19,IF($A7<=24,前提条件!$C$20,前提条件!$C$21))) -> 0 | L7: =L6*(1-前提条件!$C$22)+K7 -> 0 | M7: =L7*前提条件!$C$23 -> 0 | N7: =J7+M7 -> 330 | O7: =IF($A7<=12,前提条件!$C$25,前提条件!$C$26) -> 15000 | P7: =G7*前提条件!$C$27 -> 352.8 | Q7: =F7*前提条件!$C$28 -> 4.8 | R7: =N7*前提条件!$C$30 -> 26.4 | S7: =IF($A7<=12,前提条件!$C$31,IF($A7<=24,前提条件!$C$32,前提条件!$C$33)) -> 30000 | T7: =IF(F7>=前提条件!$C$34,前提条件!$C$35,0) -> 0 | U7: =IF(L7>=前提条件!$C$36,前提条件!$C$37,0) -> 0 | V7: =(O7+P7+Q7+R7+S7+T7+U7)*前提条件!$C$38 -> 4538.4 | W7: =O7+P7+Q7+R7+S7+T7+U7+V7 -> 49922.4 | X7: =N7-W7 -> -49592.4 | Y7: =Y6+X7 -> -99290.4
A8: 3 | B8: =C8/前提条件!$C$10 -> 648.96 | C8: =C7*(1+IF($A8<=12,前提条件!$C$7,IF($A8<=24,前提条件!$C$8,前提条件!$C$9))) -> 162.24 | D8: =D7+C8 -> 468.24 | E8: =MAX(0,E7*(1-前提条件!$C$12)+C8*前提条件!$C$11-I8) -> 170.781 | F8: =F7*(1-前提条件!$C$15)+I8 -> 2.325 | G8: =E8+F8 -> 173.106 | H8: =前提条件!$C$13*MIN(1,$A8/前提条件!$C$14) -> 0.015 | I8: =E7*H8 -> 1.755 | J8: =F8*前提条件!$C$16 -> 1278.75 | K8: =IF($A8<前提条件!$C$18,0,IF($A8<=12,前提条件!$C$19,IF($A8<=24,前提条件!$C$20,前提条件!$C$21))) -> 0 | L8: =L7*(1-前提条件!$C$22)+K8 -> 0 | M8: =L8*前提条件!$C$23 -> 0 | N8: =J8+M8 -> 1278.75 | O8: =IF($A8<=12,前提条件!$C$25,前提条件!$C$26) -> 15000 | P8: =G8*前提条件!$C$27 -> 519.318 | Q8: =F8*前提条件!$C$28 -> 18.6 | R8: =N8*前提条件!$C$30 -> 102.3 | S8: =IF($A8<=12,前提条件!$C$31,IF($A8<=24,前提条件!$C$32,前提条件!$C$33)) -> 30000 | T8: =IF(F8>=前提条件!$C$34,前提条件!$C$35,0) -> 0 | U8: =IF(L8>=前提条件!$C$36,前提条件!$C$37,0) -> 0 | V8: =(O8+P8+Q8+R8+S8+T8+U8)*前提条件!$C$38 -> 4564.0218 | W8: =O8+P8+Q8+R8+S8+T8+U8+V8 -> 50204.24 | X8: =N8-W8 -> -48925.49 | Y8: =Y7+X8 -> -148215.89
A9: 4 | B9: =C9/前提条件!$C$10 -> 674.9184 | C9: =C8*(1+IF($A9<=12,前提条件!$C$7,IF($A9<=24,前提条件!$C$8,前提条件!$C$9))) -> 168.7296 | D9: =D8+C9 -> 636.9696 | E9: =MAX(0,E8*(1-前提条件!$C$12)+C9*前提条件!$C$11-I9) -> 221.19474 | F9: =F8*(1-前提条件!$C$15)+I9 -> 5.62437 | G9: =E9+F9 -> 226.81911 | H9: =前提条件!$C$13*MIN(1,$A9/前提条件!$C$14) -> 0.02 | I9: =E8*H9 -> 3.41562 | J9: =F9*前提条件!$C$16 -> 3093.4035 | K9: =IF($A9<前提条件!$C$18,0,IF($A9<=12,前提条件!$C$19,IF($A9<=24,前提条件!$C$20,前提条件!$C$21))) -> 0 | L9: =L8*(1-前提条件!$C$22)+K9 -> 0 | M9: =L9*前提条件!$C$23 -> 0 | N9: =J9+M9 -> 3093.4035 | O9: =IF($A9<=12,前提条件!$C$25,前提条件!$C$26) -> 15000 | P9: =G9*前提条件!$C$27 -> 680.45733 | Q9: =F9*前提条件!$C$28 -> 44.99496 | R9: =N9*前提条件!$C$30 -> 247.47228 | S9: =IF($A9<=12,前提条件!$C$31,IF($A9<=24,前提条件!$C$32,前提条件!$C$33)) -> 30000 | T9: =IF(F9>=前提条件!$C$34,前提条件!$C$35,0) -> 0 | U9: =IF(L9>=前提条件!$C$36,前提条件!$C$37,0) -> 0 | V9: =(O9+P9+Q9+R9+S9+T9+U9)*前提条件!$C$38 -> 4597.2925 | W9: =O9+P9+Q9+R9+S9+T9+U9+V9 -> 50570.217 | X9: =N9-W9 -> -47476.814 | Y9: =Y8+X9 -> -195692.7
A10: 5 | B10: =C10/前提条件!$C$10 -> 701.91514 | C10: =C9*(1+IF($A10<=12,前提条件!$C$7,IF($A10<=24,前提条件!$C$8,前提条件!$C$9))) -> 175.47878 | D10: =D9+C10 -> 812.44838 | E10: =MAX(0,E9*(1-前提条件!$C$12)+C10*前提条件!$C$11-I10) -> 268.16081 | F10: =F9*(1-前提条件!$C$15)+I10 -> 10.87302 | G10: =E10+F10 -> 279.03383 | H10: =前提条件!$C$13*MIN(1,$A10/前提条件!$C$14) -> 0.025 | I10: =E9*H10 -> 5.5298685 | J10: =F10*前提条件!$C$16 -> 5980.161 | K10: =IF($A10<前提条件!$C$18,0,IF($A10<=12,前提条件!$C$19,IF($A10<=24,前提条件!$C$20,前提条件!$C$21))) -> 0 | L10: =L9*(1-前提条件!$C$22)+K10 -> 0 | M10: =L10*前提条件!$C$23 -> 0 | N10: =J10+M10 -> 5980.161 | O10: =IF($A10<=12,前提条件!$C$25,前提条件!$C$26) -> 15000 | P10: =G10*前提条件!$C$27 -> 837.10148 | Q10: =F10*前提条件!$C$28 -> 86.98416 | R10: =N10*前提条件!$C$30 -> 478.41288 | S10: =IF($A10<=12,前提条件!$C$31,IF($A10<=24,前提条件!$C$32,前提条件!$C$33)) -> 30000 | T10: =IF(F10>=前提条件!$C$34,前提条件!$C$35,0) -> 0 | U10: =IF(L10>=前提条件!$C$36,前提条件!$C$37,0) -> 0 | V10: =(O10+P10+Q10+R10+S10+T10+U10)*前提条件!$C$38 -> 4640.2499 | W10: =O10+P10+Q10+R10+S10+T10+U10+V10 -> 51042.748 | X10: =N10-W10 -> -45062.587 | Y10: =Y9+X10 -> -240755.29
A11: 6 | B11: =C11/前提条件!$C$10 -> 729.99174 | C11: =C10*(1+IF($A11<=12,前提条件!$C$7,IF($A11<=24,前提条件!$C$8,前提条件!$C$9))) -> 182.49794 | D11: =D10+C11 -> 994.94632 | E11: =MAX(0,E10*(1-前提条件!$C$12)+C11*前提条件!$C$11-I11) -> 311.66229 | F11: =F10*(1-前提条件!$C$15)+I11 -> 18.374193 | G11: =E11+F11 -> 330.03648 | H11: =前提条件!$C$13*MIN(1,$A11/前提条件!$C$14) -> 0.03 | I11: =E10*H11 -> 8.0448242 | J11: =F11*前提条件!$C$16 -> 10105.806 | K11: =IF($A11<前提条件!$C$18,0,IF($A11<=12,前提条件!$C$19,IF($A11<=24,前提条件!$C$20,前提条件!$C$21))) -> 0 | L11: =L10*(1-前提条件!$C$22)+K11 -> 0 | M11: =L11*前提条件!$C$23 -> 0 | N11: =J11+M11 -> 10105.806 | O11: =IF($A11<=12,前提条件!$C$25,前提条件!$C$26) -> 15000 | P11: =G11*前提条件!$C$27 -> 990.10945 | Q11: =F11*前提条件!$C$28 -> 146.99355 | R11: =N11*前提条件!$C$30 -> 808.4645 | S11: =IF($A11<=12,前提条件!$C$31,IF($A11<=24,前提条件!$C$32,前提条件!$C$33)) -> 30000 | T11: =IF(F11>=前提条件!$C$34,前提条件!$C$35,0) -> 0 | U11: =IF(L11>=前提条件!$C$36,前提条件!$C$37,0) -> 0 | V11: =(O11+P11+Q11+R11+S11+T11+U11)*前提条件!$C$38 -> 4694.5567 | W11: =O11+P11+Q11+R11+S11+T11+U11+V11 -> 51640.124 | X11: =N11-W11 -> -41534.318 | Y11: =Y10+X11 -> -282289.61
A12: 7 | B12: =C12/前提条件!$C$10 -> 759.19141 | C12: =C11*(1+IF($A12<=12,前提条件!$C$7,IF($A12<=24,前提条件!$C$8,前提条件!$C$9))) -> 189.79785 | D12: =D11+C12 -> 1184.7442 | E12: =MAX(0,E11*(1-前提条件!$C$12)+C12*前提条件!$C$11-I12) -> 353.29858 | F12: =F11*(1-前提条件!$C$15)+I12 -> 26.805352 | G12: =E12+F12 -> 380.10393 | H12: =前提条件!$C$13*MIN(1,$A12/前提条件!$C$14) -> 0.03 | I12: =E11*H12 -> 9.3498687 | J12: =F12*前提条件!$C$16 -> 14742.944 | K12: =IF($A12<前提条件!$C$18,0,IF($A12<=12,前提条件!$C$19,IF($A12<=24,前提条件!$C$20,前提条件!$C$21))) -> 0.3 | L12: =L11*(1-前提条件!$C$22)+K12 -> 0.3 | M12: =L12*前提条件!$C$23 -> 600 | N12: =J12+M12 -> 15342.944 | O12: =IF($A12<=12,前提条件!$C$25,前提条件!$C$26) -> 15000 | P12: =G12*前提条件!$C$27 -> 1140.3118 | Q12: =F12*前提条件!$C$28 -> 214.44282 | R12: =N12*前提条件!$C$30 -> 1227.4355 | S12: =IF($A12<=12,前提条件!$C$31,IF($A12<=24,前提条件!$C$32,前提条件!$C$33)) -> 30000 | T12: =IF(F12>=前提条件!$C$34,前提条件!$C$35,0) -> 0 | U12: =IF(L12>=前提条件!$C$36,前提条件!$C$37,0) -> 0 | V12: =(O12+P12+Q12+R12+S12+T12+U12)*前提条件!$C$38 -> 4758.219 | W12: =O12+P12+Q12+R12+S12+T12+U12+V12 -> 52340.409 | X12: =N12-W12 -> -36997.465 | Y12: =Y11+X12 -> -319287.07
A13: 8 | B13: =C13/前提条件!$C$10 -> 789.55907 | C13: =C12*(1+IF($A13<=12,前提条件!$C$7,IF($A13<=24,前提条件!$C$8,前提条件!$C$9))) -> 197.38977 | D13: =D12+C13 -> 1382.1339 | E13: =MAX(0,E12*(1-前提条件!$C$12)+C13*前提条件!$C$11-I13) -> 393.39164 | F13: =F12*(1-前提条件!$C$15)+I13 -> 36.064042 | G13: =E13+F13 -> 429.45569 | H13: =前提条件!$C$13*MIN(1,$A13/前提条件!$C$14) -> 0.03 | I13: =E12*H13 -> 10.598957 | J13: =F13*前提条件!$C$16 -> 19835.223 | K13: =IF($A13<前提条件!$C$18,0,IF($A13<=12,前提条件!$C$19,IF($A13<=24,前提条件!$C$20,前提条件!$C$21))) -> 0.3 | L13: =L12*(1-前提条件!$C$22)+K13 -> 0.588 | M13: =L13*前提条件!$C$23 -> 1176 | N13: =J13+M13 -> 21011.223 | O13: =IF($A13<=12,前提条件!$C$25,前提条件!$C$26) -> 15000 | P13: =G13*前提条件!$C$27 -> 1288.3671 | Q13: =F13*前提条件!$C$28 -> 288.51234 | R13: =N13*前提条件!$C$30 -> 1680.8979 | S13: =IF($A13<=12,前提条件!$C$31,IF($A13<=24,前提条件!$C$32,前提条件!$C$33)) -> 30000 | T13: =IF(F13>=前提条件!$C$34,前提条件!$C$35,0) -> 0 | U13: =IF(L13>=前提条件!$C$36,前提条件!$C$37,0) -> 0 | V13: =(O13+P13+Q13+R13+S13+T13+U13)*前提条件!$C$38 -> 4825.7777 | W13: =O13+P13+Q13+R13+S13+T13+U13+V13 -> 53083.555 | X13: =N13-W13 -> -32072.332 | Y13: =Y12+X13 -> -351359.41
A14: 9 | B14: =C14/前提条件!$C$10 -> 821.14143 | C14: =C13*(1+IF($A14<=12,前提条件!$C$7,IF($A14<=24,前提条件!$C$8,前提条件!$C$9))) -> 205.28536 | D14: =D13+C14 -> 1587.4193 | E14: =MAX(0,E13*(1-前提条件!$C$12)+C14*前提条件!$C$11-I14) -> 432.23271 | F14: =F13*(1-前提条件!$C$15)+I14 -> 46.062589 | G14: =E14+F14 -> 478.29529 | H14: =前提条件!$C$13*MIN(1,$A14/前提条件!$C$14) -> 0.03 | I14: =E13*H14 -> 11.801749 | J14: =F14*前提条件!$C$16 -> 25334.424 | K14: =IF($A14<前提条件!$C$18,0,IF($A14<=12,前提条件!$C$19,IF($A14<=24,前提条件!$C$20,前提条件!$C$21))) -> 0.3 | L14: =L13*(1-前提条件!$C$22)+K14 -> 0.86448 | M14: =L14*前提条件!$C$23 -> 1728.96 | N14: =J14+M14 -> 27063.384 | O14: =IF($A14<=12,前提条件!$C$25,前提条件!$C$26) -> 15000 | P14: =G14*前提条件!$C$27 -> 1434.8859 | Q14: =F14*前提条件!$C$28 -> 368.50071 | R14: =N14*前提条件!$C$30 -> 2165.0707 | S14: =IF($A14<=12,前提条件!$C$31,IF($A14<=24,前提条件!$C$32,前提条件!$C$33)) -> 30000 | T14: =IF(F14>=前提条件!$C$34,前提条件!$C$35,0) -> 0 | U14: =IF(L14>=前提条件!$C$36,前提条件!$C$37,0) -> 0 | V14: =(O14+P14+Q14+R14+S14+T14+U14)*前提条件!$C$38 -> 4896.8457 | W14: =O14+P14+Q14+R14+S14+T14+U14+V14 -> 53865.303 | X14: =N14-W14 -> -26801.919 | Y14: =Y13+X14 -> -378161.32
A15: 10 | B15: =C15/前提条件!$C$10 -> 853.98709 | C15: =C14*(1+IF($A15<=12,前提条件!$C$7,IF($A15<=24,前提条件!$C$8,前提条件!$C$9))) -> 213.49677 | D15: =D14+C15 -> 1800.9161 | E15: =MAX(0,E14*(1-前提条件!$C$12)+C15*前提条件!$C$11-I15) -> 470.08582 | F15: =F14*(1-前提条件!$C$15)+I15 -> 56.726441 | G15: =E15+F15 -> 526.81226 | H15: =前提条件!$C$13*MIN(1,$A15/前提条件!$C$14) -> 0.03 | I15: =E14*H15 -> 12.966981 | J15: =F15*前提条件!$C$16 -> 31199.543 | K15: =IF($A15<前提条件!$C$18,0,IF($A15<=12,前提条件!$C$19,IF($A15<=24,前提条件!$C$20,前提条件!$C$21))) -> 0.3 | L15: =L14*(1-前提条件!$C$22)+K15 -> 1.1299008 | M15: =L15*前提条件!$C$23 -> 2259.8016 | N15: =J15+M15 -> 33459.344 | O15: =IF($A15<=12,前提条件!$C$25,前提条件!$C$26) -> 15000 | P15: =G15*前提条件!$C$27 -> 1580.4368 | Q15: =F15*前提条件!$C$28 -> 453.81153 | R15: =N15*前提条件!$C$30 -> 2676.7475 | S15: =IF($A15<=12,前提条件!$C$31,IF($A15<=24,前提条件!$C$32,前提条件!$C$33)) -> 30000 | T15: =IF(F15>=前提条件!$C$34,前提条件!$C$35,0) -> 0 | U15: =IF(L15>=前提条件!$C$36,前提条件!$C$37,0) -> 0 | V15: =(O15+P15+Q15+R15+S15+T15+U15)*前提条件!$C$38 -> 4971.0996 | W15: =O15+P15+Q15+R15+S15+T15+U15+V15 -> 54682.095 | X15: =N15-W15 -> -21222.751 | Y15: =Y14+X15 -> -399384.08
A16: 11 | B16: =C16/前提条件!$C$10 -> 888.14657 | C16: =C15*(1+IF($A16<=12,前提条件!$C$7,IF($A16<=24,前提条件!$C$8,前提条件!$C$9))) -> 222.03664 | D16: =D15+C16 -> 2022.9527 | E16: =MAX(0,E15*(1-前提条件!$C$12)+C16*前提条件!$C$11-I16) -> 507.19103 | F16: =F15*(1-前提条件!$C$15)+I16 -> 67.992693 | G16: =E16+F16 -> 575.18373 | H16: =前提条件!$C$13*MIN(1,$A16/前提条件!$C$14) -> 0.03 | I16: =E15*H16 -> 14.102575 | J16: =F16*前提条件!$C$16 -> 37395.981 | K16: =IF($A16<前提条件!$C$18,0,IF($A16<=12,前提条件!$C$19,IF($A16<=24,前提条件!$C$20,前提条件!$C$21))) -> 0.3 | L16: =L15*(1-前提条件!$C$22)+K16 -> 1.3847048 | M16: =L16*前提条件!$C$23 -> 2769.4095 | N16: =J16+M16 -> 40165.391 | O16: =IF($A16<=12,前提条件!$C$25,前提条件!$C$26) -> 15000 | P16: =G16*前提条件!$C$27 -> 1725.5512 | Q16: =F16*前提条件!$C$28 -> 543.94155 | R16: =N16*前提条件!$C$30 -> 3213.2313 | S16: =IF($A16<=12,前提条件!$C$31,IF($A16<=24,前提条件!$C$32,前提条件!$C$33)) -> 30000 | T16: =IF(F16>=前提条件!$C$34,前提条件!$C$35,0) -> 0 | U16: =IF(L16>=前提条件!$C$36,前提条件!$C$37,0) -> 0 | V16: =(O16+P16+Q16+R16+S16+T16+U16)*前提条件!$C$38 -> 5048.2724 | W16: =O16+P16+Q16+R16+S16+T16+U16+V16 -> 55530.996 | X16: =N16-W16 -> -15365.605 | Y16: =Y15+X16 -> -414749.68
A17: 12 | B17: =C17/前提条件!$C$10 -> 923.67243 | C17: =C16*(1+IF($A17<=12,前提条件!$C$7,IF($A17<=24,前提条件!$C$8,前提条件!$C$9))) -> 230.91811 | D17: =D16+C17 -> 2253.8708 | E17: =MAX(0,E16*(1-前提条件!$C$12)+C17*前提条件!$C$11-I17) -> 543.76726 | F17: =F16*(1-前提条件!$C$15)+I17 -> 79.80879 | G17: =E17+F17 -> 623.57605 | H17: =前提条件!$C$13*MIN(1,$A17/前提条件!$C$14) -> 0.03 | I17: =E16*H17 -> 15.215731 | J17: =F17*前提条件!$C$16 -> 43894.834 | K17: =IF($A17<前提条件!$C$18,0,IF($A17<=12,前提条件!$C$19,IF($A17<=24,前提条件!$C$20,前提条件!$C$21))) -> 0.3 | L17: =L16*(1-前提条件!$C$22)+K17 -> 1.6293166 | M17: =L17*前提条件!$C$23 -> 3258.6332 | N17: =J17+M17 -> 47153.468 | O17: =IF($A17<=12,前提条件!$C$25,前提条件!$C$26) -> 15000 | P17: =G17*前提条件!$C$27 -> 1870.7282 | Q17: =F17*前提条件!$C$28 -> 638.47032 | R17: =N17*前提条件!$C$30 -> 3772.2774 | S17: =IF($A17<=12,前提条件!$C$31,IF($A17<=24,前提条件!$C$32,前提条件!$C$33)) -> 30000 | T17: =IF(F17>=前提条件!$C$34,前提条件!$C$35,0) -> 0 | U17: =IF(L17>=前提条件!$C$36,前提条件!$C$37,0) -> 0 | V17: =(O17+P17+Q17+R17+S17+T17+U17)*前提条件!$C$38 -> 5128.1476 | W17: =O17+P17+Q17+R17+S17+T17+U17+V17 -> 56409.623 | X17: =N17-W17 -> -9256.1559 | Y17: =Y16+X17 -> -424005.84
A18: 13 | B18: =C18/前提条件!$C$10 -> 942.14588 | C18: =C17*(1+IF($A18<=12,前提条件!$C$7,IF($A18<=24,前提条件!$C$8,前提条件!$C$9))) -> 235.53647 | D18: =D17+C18 -> 2489.4073 | E18: =MAX(0,E17*(1-前提条件!$C$12)+C18*前提条件!$C$11-I18) -> 578.16745 | F18: =F17*(1-前提条件!$C$15)+I18 -> 92.131368 | G18: =E18+F18 -> 670.29882 | H18: =前提条件!$C$13*MIN(1,$A18/前提条件!$C$14) -> 0.03 | I18: =E17*H18 -> 16.313018 | J18: =F18*前提条件!$C$16 -> 50672.253 | K18: =IF($A18<前提条件!$C$18,0,IF($A18<=12,前提条件!$C$19,IF($A18<=24,前提条件!$C$20,前提条件!$C$21))) -> 0.5 | L18: =L17*(1-前提条件!$C$22)+K18 -> 2.0641439 | M18: =L18*前提条件!$C$23 -> 4128.2878 | N18: =J18+M18 -> 54800.54 | O18: =IF($A18<=12,前提条件!$C$25,前提条件!$C$26) -> 25000 | P18: =G18*前提条件!$C$27 -> 2010.8965 | Q18: =F18*前提条件!$C$28 -> 737.05095 | R18: =N18*前提条件!$C$30 -> 4384.0432 | S18: =IF($A18<=12,前提条件!$C$31,IF($A18<=24,前提条件!$C$32,前提条件!$C$33)) -> 40000 | T18: =IF(F18>=前提条件!$C$34,前提条件!$C$35,0) -> 0 | U18: =IF(L18>=前提条件!$C$36,前提条件!$C$37,0) -> 0 | V18: =(O18+P18+Q18+R18+S18+T18+U18)*前提条件!$C$38 -> 7213.1991 | W18: =O18+P18+Q18+R18+S18+T18+U18+V18 -> 79345.19 | X18: =N18-W18 -> -24544.649 | Y18: =Y17+X18 -> -448550.49
... A41: 36 | B41: =C41/前提条件!$C$10 -> 1320.0079 | C41: =C40*(1+IF($A41<=12,前提条件!$C$7,IF($A41<=24,前提条件!$C$8,前提条件!$C$9))) -> 330.00197 | D41: =D40+C41 -> 9164.2469 | E41: =MAX(0,E40*(1-前提条件!$C$12)+C41*前提条件!$C$11-I41) -> 1083.4604 | F41: =F40*(1-前提条件!$C$15)+I41 -> 403.88023 | G41: =E41+F41 -> 1487.3406 | H41: =前提条件!$C$13*MIN(1,$A41/前提条件!$C$14) -> 0.03 | I41: =E40*H41 -> 32.071672 | J41: =F41*前提条件!$C$16 -> 222134.13 | K41: =IF($A41<前提条件!$C$18,0,IF($A41<=12,前提条件!$C$19,IF($A41<=24,前提条件!$C$20,前提条件!$C$21))) -> 0.8 | L41: =L40*(1-前提条件!$C$22)+K41 -> 11.323678 | M41: =L41*前提条件!$C$23 -> 22647.357 | N41: =J41+M41 -> 244781.48 | O41: =IF($A41<=12,前提条件!$C$25,前提条件!$C$26) -> 25000 | P41: =G41*前提条件!$C$27 -> 4462.0219 | Q41: =F41*前提条件!$C$28 -> 3231.0418 | R41: =N41*前提条件!$C$30 -> 19582.519 | S41: =IF($A41<=12,前提条件!$C$31,IF($A41<=24,前提条件!$C$32,前提条件!$C$33)) -> 50000 | T41: =IF(F41>=前提条件!$C$34,前提条件!$C$35,0) -> 0 | U41: =IF(L41>=前提条件!$C$36,前提条件!$C$37,0) -> 80000 | V41: =(O41+P41+Q41+R41+S41+T41+U41)*前提条件!$C$38 -> 18227.558 | W41: =O41+P41+Q41+R41+S41+T41+U41+V41 -> 200503.14 | X41: =N41-W41 -> 44278.343 | Y41: =Y40+X41 -> 519733.6

Sheet 標準ケース
A1: 現場でんき探偵Pro ― 標準ケース（月次モデル・36ヶ月）
A2: 青文字セルなし＝本シートは全セルが数式。入力値は「前提条件」シートで編集してください。
A4: 月 | B4: ストア閲覧数 | C4: 新規DL数 | D4: 累計DL数 | E4: 無料会員数 | F4: 有料会員数(個人) | G4: MAU(月間利用者数) | H4: 当月転換率(無料→有料) | I4: 新規有料転換数 | J4: 個人課金売上(円) | K4: 法人新規契約数 | L4: 法人契約数累計 | M4: 法人売上(円) | N4: 売上合計(円) | O4: サーバー・インフラ費 | P4: Firebase従量費 | Q4: AI API費(限定AI版) | R4: 決済・ストア手数料 | S4: 広告・マーケティング費 | T4: CS費 | U4: 法人営業費 | V4: 予備費 | W4: 費用合計(円) | X4: 月次損益(円) | Y4: 累計損益(円)
A5: 0 | B5: 0 | C5: 0 | D5: 0 | E5: 0 | F5: 0 | G5: 0 | H5: 0 | I5: 0 | J5: 0 | K5: 0 | L5: 0 | M5: 0 | N5: 0 | O5: 0 | P5: 0 | Q5: 0 | R5: 0 | S5: 0 | T5: 0 | U5: 0 | V5: 0 | W5: 0 | X5: 0 | Y5: 0
A6: 1 | B6: =C6/前提条件!$D$10 -> 1000 | C6: =前提条件!$D$6 -> 300 | D6: =D5+C6 -> 300 | E6: =MAX(0,E5*(1-前提条件!$D$12)+C6*前提条件!$D$11-I6) -> 135 | F6: =F5*(1-前提条件!$D$15)+I6 -> 0 | G6: =E6+F6 -> 135 | H6: =前提条件!$D$13*MIN(1,$A6/前提条件!$D$14) -> 0.01 | I6: =E5*H6 -> 0 | J6: =F6*前提条件!$D$16 -> 0 | K6: =IF($A6<前提条件!$D$18,0,IF($A6<=12,前提条件!$D$19,IF($A6<=24,前提条件!$D$20,前提条件!$D$21))) -> 0 | L6: =L5*(1-前提条件!$D$22)+K6 -> 0 | M6: =L6*前提条件!$D$23 -> 0 | N6: =J6+M6 -> 0 | O6: =IF($A6<=12,前提条件!$D$25,前提条件!$D$26) -> 15000 | P6: =G6*前提条件!$D$27 -> 405 | Q6: =F6*前提条件!$D$28 -> 0 | R6: =N6*前提条件!$D$30 -> 0 | S6: =IF($A6<=12,前提条件!$D$31,IF($A6<=24,前提条件!$D$32,前提条件!$D$33)) -> 80000 | T6: =IF(F6>=前提条件!$D$34,前提条件!$D$35,0) -> 0 | U6: =IF(L6>=前提条件!$D$36,前提条件!$D$37,0) -> 0 | V6: =(O6+P6+Q6+R6+S6+T6+U6)*前提条件!$D$38 -> 9540.5 | W6: =O6+P6+Q6+R6+S6+T6+U6+V6 -> 104945.5 | X6: =N6-W6 -> -104945.5 | Y6: =Y5+X6 -> -104945.5
A7: 2 | B7: =C7/前提条件!$D$10 -> 1070 | C7: =C6*(1+IF($A7<=12,前提条件!$D$7,IF($A7<=24,前提条件!$D$8,前提条件!$D$9))) -> 321 | D7: =D6+C7 -> 621 | E7: =MAX(0,E6*(1-前提条件!$D$12)+C7*前提条件!$D$11-I7) -> 267.3 | F7: =F6*(1-前提条件!$D$15)+I7 -> 2.7 | G7: =E7+F7 -> 270 | H7: =前提条件!$D$13*MIN(1,$A7/前提条件!$D$14) -> 0.02 | I7: =E6*H7 -> 2.7 | J7: =F7*前提条件!$D$16 -> 1674 | K7: =IF($A7<前提条件!$D$18,0,IF($A7<=12,前提条件!$D$19,IF($A7<=24,前提条件!$D$20,前提条件!$D$21))) -> 0 | L7: =L6*(1-前提条件!$D$22)+K7 -> 0 | M7: =L7*前提条件!$D$23 -> 0 | N7: =J7+M7 -> 1674 | O7: =IF($A7<=12,前提条件!$D$25,前提条件!$D$26) -> 15000 | P7: =G7*前提条件!$D$27 -> 810 | Q7: =F7*前提条件!$D$28 -> 21.6 | R7: =N7*前提条件!$D$30 -> 133.92 | S7: =IF($A7<=12,前提条件!$D$31,IF($A7<=24,前提条件!$D$32,前提条件!$D$33)) -> 80000 | T7: =IF(F7>=前提条件!$D$34,前提条件!$D$35,0) -> 0 | U7: =IF(L7>=前提条件!$D$36,前提条件!$D$37,0) -> 0 | V7: =(O7+P7+Q7+R7+S7+T7+U7)*前提条件!$D$38 -> 9596.552 | W7: =O7+P7+Q7+R7+S7+T7+U7+V7 -> 105562.07 | X7: =N7-W7 -> -103888.07 | Y7: =Y6+X7 -> -208833.57
A8: 3 | B8: =C8/前提条件!$D$10 -> 1144.9 | C8: =C7*(1+IF($A8<=12,前提条件!$D$7,IF($A8<=24,前提条件!$D$8,前提条件!$D$9))) -> 343.47 | D8: =D7+C8 -> 964.47 | E8: =MAX(0,E7*(1-前提条件!$D$12)+C8*前提条件!$D$11-I8) -> 395.1315 | F8: =F7*(1-前提条件!$D$15)+I8 -> 10.611 | G8: =E8+F8 -> 405.7425 | H8: =前提条件!$D$13*MIN(1,$A8/前提条件!$D$14) -> 0.03 | I8: =E7*H8 -> 8.019 | J8: =F8*前提条件!$D$16 -> 6578.82 | K8: =IF($A8<前提条件!$D$18,0,IF($A8<=12,前提条件!$D$19,IF($A8<=24,前提条件!$D$20,前提条件!$D$21))) -> 0 | L8: =L7*(1-前提条件!$D$22)+K8 -> 0 | M8: =L8*前提条件!$D$23 -> 0 | N8: =J8+M8 -> 6578.82 | O8: =IF($A8<=12,前提条件!$D$25,前提条件!$D$26) -> 15000 | P8: =G8*前提条件!$D$27 -> 1217.2275 | Q8: =F8*前提条件!$D$28 -> 84.888 | R8: =N8*前提条件!$D$30 -> 526.3056 | S8: =IF($A8<=12,前提条件!$D$31,IF($A8<=24,前提条件!$D$32,前提条件!$D$33)) -> 80000 | T8: =IF(F8>=前提条件!$D$34,前提条件!$D$35,0) -> 0 | U8: =IF(L8>=前提条件!$D$36,前提条件!$D$37,0) -> 0 | V8: =(O8+P8+Q8+R8+S8+T8+U8)*前提条件!$D$38 -> 9682.8421 | W8: =O8+P8+Q8+R8+S8+T8+U8+V8 -> 106511.26 | X8: =N8-W8 -> -99932.443 | Y8: =Y7+X8 -> -308766.02
A9: 4 | B9: =C9/前提条件!$D$10 -> 1225.043 | C9: =C8*(1+IF($A9<=12,前提条件!$D$7,IF($A9<=24,前提条件!$D$8,前提条件!$D$9))) -> 367.5129 | D9: =D8+C9 -> 1331.9829 | E9: =MAX(0,E8*(1-前提条件!$D$12)+C9*前提条件!$D$11-I9) -> 517.04784 | F9: =F8*(1-前提条件!$D$15)+I9 -> 25.99182 | G9: =E9+F9 -> 543.03966 | H9: =前提条件!$D$13*MIN(1,$A9/前提条件!$D$14) -> 0.04 | I9: =E8*H9 -> 15.80526 | J9: =F9*前提条件!$D$16 -> 16114.928 | K9: =IF($A9<前提条件!$D$18,0,IF($A9<=12,前提条件!$D$19,IF($A9<=24,前提条件!$D$20,前提条件!$D$21))) -> 0 | L9: =L8*(1-前提条件!$D$22)+K9 -> 0 | M9: =L9*前提条件!$D$23 -> 0 | N9: =J9+M9 -> 16114.928 | O9: =IF($A9<=12,前提条件!$D$25,前提条件!$D$26) -> 15000 | P9: =G9*前提条件!$D$27 -> 1629.119 | Q9: =F9*前提条件!$D$28 -> 207.93456 | R9: =N9*前提条件!$D$30 -> 1289.1943 | S9: =IF($A9<=12,前提条件!$D$31,IF($A9<=24,前提条件!$D$32,前提条件!$D$33)) -> 80000 | T9: =IF(F9>=前提条件!$D$34,前提条件!$D$35,0) -> 0 | U9: =IF(L9>=前提条件!$D$36,前提条件!$D$37,0) -> 0 | V9: =(O9+P9+Q9+R9+S9+T9+U9)*前提条件!$D$38 -> 9812.6248 | W9: =O9+P9+Q9+R9+S9+T9+U9+V9 -> 107938.87 | X9: =N9-W9 -> -91823.944 | Y9: =Y8+X9 -> -400589.96
A10: 5 | B10: =C10/前提条件!$D$10 -> 1310.796 | C10: =C9*(1+IF($A10<=12,前提条件!$D$7,IF($A10<=24,前提条件!$D$8,前提条件!$D$9))) -> 393.2388 | D10: =D9+C10 -> 1725.2217 | E10: =MAX(0,E9*(1-前提条件!$D$12)+C10*前提条件!$D$11-I10) -> 631.95956 | F10: =F9*(1-前提条件!$D$15)+I10 -> 50.804539 | G10: =E10+F10 -> 682.7641 | H10: =前提条件!$D$13*MIN(1,$A10/前提条件!$D$14) -> 0.05 | I10: =E9*H10 -> 25.852392 | J10: =F10*前提条件!$D$16 -> 31498.814 | K10: =IF($A10<前提条件!$D$18,0,IF($A10<=12,前提条件!$D$19,IF($A10<=24,前提条件!$D$20,前提条件!$D$21))) -> 1 | L10: =L9*(1-前提条件!$D$22)+K10 -> 1 | M10: =L10*前提条件!$D$23 -> 2600 | N10: =J10+M10 -> 34098.814 | O10: =IF($A10<=12,前提条件!$D$25,前提条件!$D$26) -> 15000 | P10: =G10*前提条件!$D$27 -> 2048.2923 | Q10: =F10*前提条件!$D$28 -> 406.43631 | R10: =N10*前提条件!$D$30 -> 2727.9051 | S10: =IF($A10<=12,前提条件!$D$31,IF($A10<=24,前提条件!$D$32,前提条件!$D$33)) -> 80000 | T10: =IF(F10>=前提条件!$D$34,前提条件!$D$35,0) -> 0 | U10: =IF(L10>=前提条件!$D$36,前提条件!$D$37,0) -> 0 | V10: =(O10+P10+Q10+R10+S10+T10+U10)*前提条件!$D$38 -> 10018.263 | W10: =O10+P10+Q10+R10+S10+T10+U10+V10 -> 110200.9 | X10: =N10-W10 -> -76102.083 | Y10: =Y9+X10 -> -476692.04
A11: 6 | B11: =C11/前提条件!$D$10 -> 1402.5517 | C11: =C10*(1+IF($A11<=12,前提条件!$D$7,IF($A11<=24,前提条件!$D$8,前提条件!$D$9))) -> 420.76552 | D11: =D10+C11 -> 2145.9872 | E11: =MAX(0,E10*(1-前提条件!$D$12)+C11*前提条件!$D$11-I11) -> 745.4689 | F11: =F10*(1-前提条件!$D$15)+I11 -> 80.370336 | G11: =E11+F11 -> 825.83923 | H11: =前提条件!$D$13*MIN(1,$A11/前提条件!$D$14) -> 0.05 | I11: =E10*H11 -> 31.597978 | J11: =F11*前提条件!$D$16 -> 49829.608 | K11: =IF($A11<前提条件!$D$18,0,IF($A11<=12,前提条件!$D$19,IF($A11<=24,前提条件!$D$20,前提条件!$D$21))) -> 1 | L11: =L10*(1-前提条件!$D$22)+K11 -> 1.975 | M11: =L11*前提条件!$D$23 -> 5135 | N11: =J11+M11 -> 54964.608 | O11: =IF($A11<=12,前提条件!$D$25,前提条件!$D$26) -> 15000 | P11: =G11*前提条件!$D$27 -> 2477.5177 | Q11: =F11*前提条件!$D$28 -> 642.96269 | R11: =N11*前提条件!$D$30 -> 4397.1686 | S11: =IF($A11<=12,前提条件!$D$31,IF($A11<=24,前提条件!$D$32,前提条件!$D$33)) -> 80000 | T11: =IF(F11>=前提条件!$D$34,前提条件!$D$35,0) -> 0 | U11: =IF(L11>=前提条件!$D$36,前提条件!$D$37,0) -> 0 | V11: =(O11+P11+Q11+R11+S11+T11+U11)*前提条件!$D$38 -> 10251.765 | W11: =O11+P11+Q11+R11+S11+T11+U11+V11 -> 112769.41 | X11: =N11-W11 -> -57804.806 | Y11: =Y10+X11 -> -534496.85
A12: 7 | B12: =C12/前提条件!$D$10 -> 1500.7304 | C12: =C11*(1+IF($A12<=12,前提条件!$D$7,IF($A12<=24,前提条件!$D$8,前提条件!$D$9))) -> 450.21911 | D12: =D11+C12 -> 2596.2063 | E12: =MAX(0,E11*(1-前提条件!$D$12)+C12*前提条件!$D$11-I12) -> 858.61123 | F12: =F11*(1-前提条件!$D$15)+I12 -> 114.42897 | G12: =E12+F12 -> 973.04019 | H12: =前提条件!$D$13*MIN(1,$A12/前提条件!$D$14) -> 0.05 | I12: =E11*H12 -> 37.273445 | J12: =F12*前提条件!$D$16 -> 70945.96 | K12: =IF($A12<前提条件!$D$18,0,IF($A12<=12,前提条件!$D$19,IF($A12<=24,前提条件!$D$20,前提条件!$D$21))) -> 1 | L12: =L11*(1-前提条件!$D$22)+K12 -> 2.925625 | M12: =L12*前提条件!$D$23 -> 7606.625 | N12: =J12+M12 -> 78552.585 | O12: =IF($A12<=12,前提条件!$D$25,前提条件!$D$26) -> 15000 | P12: =G12*前提条件!$D$27 -> 2919.1206 | Q12: =F12*前提条件!$D$28 -> 915.43174 | R12: =N12*前提条件!$D$30 -> 6284.2068 | S12: =IF($A12<=12,前提条件!$D$31,IF($A12<=24,前提条件!$D$32,前提条件!$D$33)) -> 80000 | T12: =IF(F12>=前提条件!$D$34,前提条件!$D$35,0) -> 0 | U12: =IF(L12>=前提条件!$D$36,前提条件!$D$37,0) -> 0 | V12: =(O12+P12+Q12+R12+S12+T12+U12)*前提条件!$D$38 -> 10511.876 | W12: =O12+P12+Q12+R12+S12+T12+U12+V12 -> 115630.63 | X12: =N12-W12 -> -37078.05 | Y12: =Y11+X12 -> -571574.9
A13: 8 | B13: =C13/前提条件!$D$10 -> 1605.7815 | C13: =C12*(1+IF($A13<=12,前提条件!$D$7,IF($A13<=24,前提条件!$D$8,前提条件!$D$9))) -> 481.73444 | D13: =D12+C13 -> 3077.9408 | E13: =MAX(0,E12*(1-前提条件!$D$12)+C13*前提条件!$D$11-I13) -> 972.35838 | F13: =F12*(1-前提条件!$D$15)+I13 -> 152.78237 | G13: =E13+F13 -> 1125.1407 | H13: =前提条件!$D$13*MIN(1,$A13/前提条件!$D$14) -> 0.05 | I13: =E12*H13 -> 42.930561 | J13: =F13*前提条件!$D$16 -> 94725.069 | K13: =IF($A13<前提条件!$D$18,0,IF($A13<=12,前提条件!$D$19,IF($A13<=24,前提条件!$D$20,前提条件!$D$21))) -> 1 | L13: =L12*(1-前提条件!$D$22)+K13 -> 3.8524844 | M13: =L13*前提条件!$D$23 -> 10016.459 | N13: =J13+M13 -> 104741.53 | O13: =IF($A13<=12,前提条件!$D$25,前提条件!$D$26) -> 15000 | P13: =G13*前提条件!$D$27 -> 3375.4222 | Q13: =F13*前提条件!$D$28 -> 1222.259 | R13: =N13*前提条件!$D$30 -> 8379.3223 | S13: =IF($A13<=12,前提条件!$D$31,IF($A13<=24,前提条件!$D$32,前提条件!$D$33)) -> 80000 | T13: =IF(F13>=前提条件!$D$34,前提条件!$D$35,0) -> 0 | U13: =IF(L13>=前提条件!$D$36,前提条件!$D$37,0) -> 0 | V13: =(O13+P13+Q13+R13+S13+T13+U13)*前提条件!$D$38 -> 10797.7 | W13: =O13+P13+Q13+R13+S13+T13+U13+V13 -> 118774.7 | X13: =N13-W13 -> -14033.175 | Y13: =Y12+X13 -> -585608.07
A14: 9 | B14: =C14/前提条件!$D$10 -> 1718.1862 | C14: =C13*(1+IF($A14<=12,前提条件!$D$7,IF($A14<=24,前提条件!$D$8,前提条件!$D$9))) -> 515.45585 | D14: =D13+C14 -> 3593.3966 | E14: =MAX(0,E13*(1-前提条件!$D$12)+C14*前提条件!$D$11-I14) -> 1087.6305 | F14: =F13*(1-前提条件!$D$15)+I14 -> 195.28899 | G14: =E14+F14 -> 1282.9195 | H14: =前提条件!$D$13*MIN(1,$A14/前提条件!$D$14) -> 0.05 | I14: =E13*H14 -> 48.617919 | J14: =F14*前提条件!$D$16 -> 121079.18 | K14: =IF($A14<前提条件!$D$18,0,IF($A14<=12,前提条件!$D$19,IF($A14<=24,前提条件!$D$20,前提条件!$D$21))) -> 1 | L14: =L13*(1-前提条件!$D$22)+K14 -> 4.7561723 | M14: =L14*前提条件!$D$23 -> 12366.048 | N14: =J14+M14 -> 133445.22 | O14: =IF($A14<=12,前提条件!$D$25,前提条件!$D$26) -> 15000 | P14: =G14*前提条件!$D$27 -> 3848.7585 | Q14: =F14*前提条件!$D$28 -> 1562.312 | R14: =N14*前提条件!$D$30 -> 10675.618 | S14: =IF($A14<=12,前提条件!$D$31,IF($A14<=24,前提条件!$D$32,前提条件!$D$33)) -> 80000 | T14: =IF(F14>=前提条件!$D$34,前提条件!$D$35,0) -> 0 | U14: =IF(L14>=前提条件!$D$36,前提条件!$D$37,0) -> 0 | V14: =(O14+P14+Q14+R14+S14+T14+U14)*前提条件!$D$38 -> 11108.669 | W14: =O14+P14+Q14+R14+S14+T14+U14+V14 -> 122195.36 | X14: =N14-W14 -> 11249.867 | Y14: =Y13+X14 -> -574358.21
A15: 10 | B15: =C15/前提条件!$D$10 -> 1838.4592 | C15: =C14*(1+IF($A15<=12,前提条件!$D$7,IF($A15<=24,前提条件!$D$8,前提条件!$D$9))) -> 551.53776 | D15: =D14+C15 -> 4144.9344 | E15: =MAX(0,E14*(1-前提条件!$D$12)+C15*前提条件!$D$11-I15) -> 1205.3068 | F15: =F14*(1-前提条件!$D$15)+I15 -> 241.85896 | G15: =E15+F15 -> 1447.1658 | H15: =前提条件!$D$13*MIN(1,$A15/前提条件!$D$14) -> 0.05 | I15: =E14*H15 -> 54.381525 | J15: =F15*前提条件!$D$16 -> 149952.55 | K15: =IF($A15<前提条件!$D$18,0,IF($A15<=12,前提条件!$D$19,IF($A15<=24,前提条件!$D$20,前提条件!$D$21))) -> 1 | L15: =L14*(1-前提条件!$D$22)+K15 -> 5.637268 | M15: =L15*前提条件!$D$23 -> 14656.897 | N15: =J15+M15 -> 164609.45 | O15: =IF($A15<=12,前提条件!$D$25,前提条件!$D$26) -> 15000 | P15: =G15*前提条件!$D$27 -> 4341.4974 | Q15: =F15*前提条件!$D$28 -> 1934.8717 | R15: =N15*前提条件!$D$30 -> 13168.756 | S15: =IF($A15<=12,前提条件!$D$31,IF($A15<=24,前提条件!$D$32,前提条件!$D$33)) -> 80000 | T15: =IF(F15>=前提条件!$D$34,前提条件!$D$35,0) -> 0 | U15: =IF(L15>=前提条件!$D$36,前提条件!$D$37,0) -> 0 | V15: =(O15+P15+Q15+R15+S15+T15+U15)*前提条件!$D$38 -> 11444.513 | W15: =O15+P15+Q15+R15+S15+T15+U15+V15 -> 125889.64 | X15: =N15-W15 -> 38719.814 | Y15: =Y14+X15 -> -535638.39
A16: 11 | B16: =C16/前提条件!$D$10 -> 1967.1514 | C16: =C15*(1+IF($A16<=12,前提条件!$D$7,IF($A16<=24,前提条件!$D$8,前提条件!$D$9))) -> 590.14541 | D16: =D15+C16 -> 4735.0798 | E16: =MAX(0,E15*(1-前提条件!$D$12)+C16*前提条件!$D$11-I16) -> 1326.2355 | F16: =F15*(1-前提条件!$D$15)+I16 -> 292.44994 | G16: =E16+F16 -> 1618.6854 | H16: =前提条件!$D$13*MIN(1,$A16/前提条件!$D$14) -> 0.05 | I16: =E15*H16 -> 60.265342 | J16: =F16*前提条件!$D$16 -> 181318.96 | K16: =IF($A16<前提条件!$D$18,0,IF($A16<=12,前提条件!$D$19,IF($A16<=24,前提条件!$D$20,前提条件!$D$21))) -> 1 | L16: =L15*(1-前提条件!$D$22)+K16 -> 6.4963363 | M16: =L16*前提条件!$D$23 -> 16890.474 | N16: =J16+M16 -> 198209.44 | O16: =IF($A16<=12,前提条件!$D$25,前提条件!$D$26) -> 15000 | P16: =G16*前提条件!$D$27 -> 4856.0562 | Q16: =F16*前提条件!$D$28 -> 2339.5995 | R16: =N16*前提条件!$D$30 -> 15856.755 | S16: =IF($A16<=12,前提条件!$D$31,IF($A16<=24,前提条件!$D$32,前提条件!$D$33)) -> 80000 | T16: =IF(F16>=前提条件!$D$34,前提条件!$D$35,0) -> 0 | U16: =IF(L16>=前提条件!$D$36,前提条件!$D$37,0) -> 0 | V16: =(O16+P16+Q16+R16+S16+T16+U16)*前提条件!$D$38 -> 11805.241 | W16: =O16+P16+Q16+R16+S16+T16+U16+V16 -> 129857.65 | X16: =N16-W16 -> 68351.787 | Y16: =Y15+X16 -> -467286.61
A17: 12 | B17: =C17/前提条件!$D$10 -> 2104.852 | C17: =C16*(1+IF($A17<=12,前提条件!$D$7,IF($A17<=24,前提条件!$D$8,前提条件!$D$9))) -> 631.45559 | D17: =D16+C17 -> 5366.5354 | E17: =MAX(0,E16*(1-前提条件!$D$12)+C17*前提条件!$D$11-I17) -> 1451.2422 | F17: =F16*(1-前提条件!$D$15)+I17 -> 347.06372 | G17: =E17+F17 -> 1798.3059 | H17: =前提条件!$D$13*MIN(1,$A17/前提条件!$D$14) -> 0.05 | I17: =E16*H17 -> 66.311773 | J17: =F17*前提条件!$D$16 -> 215179.51 | K17: =IF($A17<前提条件!$D$18,0,IF($A17<=12,前提条件!$D$19,IF($A17<=24,前提条件!$D$20,前提条件!$D$21))) -> 1 | L17: =L16*(1-前提条件!$D$22)+K17 -> 7.3339279 | M17: =L17*前提条件!$D$23 -> 19068.212 | N17: =J17+M17 -> 234247.72 | O17: =IF($A17<=12,前提条件!$D$25,前提条件!$D$26) -> 15000 | P17: =G17*前提条件!$D$27 -> 5394.9178 | Q17: =F17*前提条件!$D$28 -> 2776.5097 | R17: =N17*前提条件!$D$30 -> 18739.817 | S17: =IF($A17<=12,前提条件!$D$31,IF($A17<=24,前提条件!$D$32,前提条件!$D$33)) -> 80000 | T17: =IF(F17>=前提条件!$D$34,前提条件!$D$35,0) -> 0 | U17: =IF(L17>=前提条件!$D$36,前提条件!$D$37,0) -> 0 | V17: =(O17+P17+Q17+R17+S17+T17+U17)*前提条件!$D$38 -> 12191.124 | W17: =O17+P17+Q17+R17+S17+T17+U17+V17 -> 134102.37 | X17: =N17-W17 -> 100145.35 | Y17: =Y16+X17 -> -367141.26
A18: 13 | B18: =C18/前提条件!$D$10 -> 2189.046 | C18: =C17*(1+IF($A18<=12,前提条件!$D$7,IF($A18<=24,前提条件!$D$8,前提条件!$D$9))) -> 656.71381 | D18: =D17+C18 -> 6023.2492 | E18: =MAX(0,E17*(1-前提条件!$D$12)+C18*前提条件!$D$11-I18) -> 1572.6144 | F18: =F17*(1-前提条件!$D$15)+I18 -> 405.74328 | G18: =E18+F18 -> 1978.3576 | H18: =前提条件!$D$13*MIN(1,$A18/前提条件!$D$14) -> 0.05 | I18: =E17*H18 -> 72.562111 | J18: =F18*前提条件!$D$16 -> 251560.83 | K18: =IF($A18<前提条件!$D$18,0,IF($A18<=12,前提条件!$D$19,IF($A18<=24,前提条件!$D$20,前提条件!$D$21))) -> 1.6 | L18: =L17*(1-前提条件!$D$22)+K18 -> 8.7505797 | M18: =L18*前提条件!$D$23 -> 22751.507 | N18: =J18+M18 -> 274312.34 | O18: =IF($A18<=12,前提条件!$D$25,前提条件!$D$26) -> 30000 | P18: =G18*前提条件!$D$27 -> 5935.0729 | Q18: =F18*前提条件!$D$28 -> 3245.9462 | R18: =N18*前提条件!$D$30 -> 21944.987 | S18: =IF($A18<=12,前提条件!$D$31,IF($A18<=24,前提条件!$D$32,前提条件!$D$33)) -> 100000 | T18: =IF(F18>=前提条件!$D$34,前提条件!$D$35,0) -> 0 | U18: =IF(L18>=前提条件!$D$36,前提条件!$D$37,0) -> 0 | V18: =(O18+P18+Q18+R18+S18+T18+U18)*前提条件!$D$38 -> 16112.601 | W18: =O18+P18+Q18+R18+S18+T18+U18+V18 -> 177238.61 | X18: =N18-W18 -> 97073.734 | Y18: =Y17+X18 -> -270067.52
... A41: 36 | B41: =C41/前提条件!$D$10 -> 4273.8934 | C41: =C40*(1+IF($A41<=12,前提条件!$D$7,IF($A41<=24,前提条件!$D$8,前提条件!$D$9))) -> 1282.168 | D41: =D40+C41 -> 29064.741 | E41: =MAX(0,E40*(1-前提条件!$D$12)+C41*前提条件!$D$11-I41) -> 4108.1783 | F41: =F40*(1-前提条件!$D$15)+I41 -> 2469.9501 | G41: =E41+F41 -> 6578.1284 | H41: =前提条件!$D$13*MIN(1,$A41/前提条件!$D$14) -> 0.05 | I41: =E40*H41 -> 200.63652 | J41: =F41*前提条件!$D$16 -> 1531369.1 | K41: =IF($A41<前提条件!$D$18,0,IF($A41<=12,前提条件!$D$19,IF($A41<=24,前提条件!$D$20,前提条件!$D$21))) -> 2.2 | L41: =L40*(1-前提条件!$D$22)+K41 -> 39.425342 | M41: =L41*前提条件!$D$23 -> 102505.89 | N41: =J41+M41 -> 1633874.9 | O41: =IF($A41<=12,前提条件!$D$25,前提条件!$D$26) -> 30000 | P41: =G41*前提条件!$D$27 -> 19734.385 | Q41: =F41*前提条件!$D$28 -> 19759.601 | R41: =N41*前提条件!$D$30 -> 130710 | S41: =IF($A41<=12,前提条件!$D$31,IF($A41<=24,前提条件!$D$32,前提条件!$D$33)) -> 120000 | T41: =IF(F41>=前提条件!$D$34,前提条件!$D$35,0) -> 50000 | U41: =IF(L41>=前提条件!$D$36,前提条件!$D$37,0) -> 80000 | V41: =(O41+P41+Q41+R41+S41+T41+U41)*前提条件!$D$38 -> 45020.398 | W41: =O41+P41+Q41+R41+S41+T41+U41+V41 -> 495224.38 | X41: =N41-W41 -> 1138650.6 | Y41: =Y40+X41 -> 11792471

Sheet 好調ケース
A1: 現場でんき探偵Pro ― 好調ケース（月次モデル・36ヶ月）
A2: 青文字セルなし＝本シートは全セルが数式。入力値は「前提条件」シートで編集してください。
A4: 月 | B4: ストア閲覧数 | C4: 新規DL数 | D4: 累計DL数 | E4: 無料会員数 | F4: 有料会員数(個人) | G4: MAU(月間利用者数) | H4: 当月転換率(無料→有料) | I4: 新規有料転換数 | J4: 個人課金売上(円) | K4: 法人新規契約数 | L4: 法人契約数累計 | M4: 法人売上(円) | N4: 売上合計(円) | O4: サーバー・インフラ費 | P4: Firebase従量費 | Q4: AI API費(限定AI版) | R4: 決済・ストア手数料 | S4: 広告・マーケティング費 | T4: CS費 | U4: 法人営業費 | V4: 予備費 | W4: 費用合計(円) | X4: 月次損益(円) | Y4: 累計損益(円)
A5: 0 | B5: 0 | C5: 0 | D5: 0 | E5: 0 | F5: 0 | G5: 0 | H5: 0 | I5: 0 | J5: 0 | K5: 0 | L5: 0 | M5: 0 | N5: 0 | O5: 0 | P5: 0 | Q5: 0 | R5: 0 | S5: 0 | T5: 0 | U5: 0 | V5: 0 | W5: 0 | X5: 0 | Y5: 0
A6: 1 | B6: =C6/前提条件!$E$10 -> 1428.5714 | C6: =前提条件!$E$6 -> 500 | D6: =D5+C6 -> 500 | E6: =MAX(0,E5*(1-前提条件!$E$12)+C6*前提条件!$E$11-I6) -> 275 | F6: =F5*(1-前提条件!$E$15)+I6 -> 0 | G6: =E6+F6 -> 275 | H6: =前提条件!$E$13*MIN(1,$A6/前提条件!$E$14) -> 0.02 | I6: =E5*H6 -> 0 | J6: =F6*前提条件!$E$16 -> 0 | K6: =IF($A6<前提条件!$E$18,0,IF($A6<=12,前提条件!$E$19,IF($A6<=24,前提条件!$E$20,前提条件!$E$21))) -> 0 | L6: =L5*(1-前提条件!$E$22)+K6 -> 0 | M6: =L6*前提条件!$E$23 -> 0 | N6: =J6+M6 -> 0 | O6: =IF($A6<=12,前提条件!$E$25,前提条件!$E$26) -> 18000 | P6: =G6*前提条件!$E$27 -> 825 | Q6: =F6*前提条件!$E$28 -> 0 | R6: =N6*前提条件!$E$30 -> 0 | S6: =IF($A6<=12,前提条件!$E$31,IF($A6<=24,前提条件!$E$32,前提条件!$E$33)) -> 150000 | T6: =IF(F6>=前提条件!$E$34,前提条件!$E$35,0) -> 0 | U6: =IF(L6>=前提条件!$E$36,前提条件!$E$37,0) -> 0 | V6: =(O6+P6+Q6+R6+S6+T6+U6)*前提条件!$E$38 -> 16882.5 | W6: =O6+P6+Q6+R6+S6+T6+U6+V6 -> 185707.5 | X6: =N6-W6 -> -185707.5 | Y6: =Y5+X6 -> -185707.5
A7: 2 | B7: =C7/前提条件!$E$10 -> 1571.4286 | C7: =C6*(1+IF($A7<=12,前提条件!$E$7,IF($A7<=24,前提条件!$E$8,前提条件!$E$9))) -> 550 | D7: =D6+C7 -> 1050 | E7: =MAX(0,E6*(1-前提条件!$E$12)+C7*前提条件!$E$11-I7) -> 550 | F7: =F6*(1-前提条件!$E$15)+I7 -> 11 | G7: =E7+F7 -> 561 | H7: =前提条件!$E$13*MIN(1,$A7/前提条件!$E$14) -> 0.04 | I7: =E6*H7 -> 11 | J7: =F7*前提条件!$E$16 -> 7700 | K7: =IF($A7<前提条件!$E$18,0,IF($A7<=12,前提条件!$E$19,IF($A7<=24,前提条件!$E$20,前提条件!$E$21))) -> 0 | L7: =L6*(1-前提条件!$E$22)+K7 -> 0 | M7: =L7*前提条件!$E$23 -> 0 | N7: =J7+M7 -> 7700 | O7: =IF($A7<=12,前提条件!$E$25,前提条件!$E$26) -> 18000 | P7: =G7*前提条件!$E$27 -> 1683 | Q7: =F7*前提条件!$E$28 -> 88 | R7: =N7*前提条件!$E$30 -> 616 | S7: =IF($A7<=12,前提条件!$E$31,IF($A7<=24,前提条件!$E$32,前提条件!$E$33)) -> 150000 | T7: =IF(F7>=前提条件!$E$34,前提条件!$E$35,0) -> 0 | U7: =IF(L7>=前提条件!$E$36,前提条件!$E$37,0) -> 0 | V7: =(O7+P7+Q7+R7+S7+T7+U7)*前提条件!$E$38 -> 17038.7 | W7: =O7+P7+Q7+R7+S7+T7+U7+V7 -> 187425.7 | X7: =N7-W7 -> -179725.7 | Y7: =Y6+X7 -> -365433.2
A8: 3 | B8: =C8/前提条件!$E$10 -> 1728.5714 | C8: =C7*(1+IF($A8<=12,前提条件!$E$7,IF($A8<=24,前提条件!$E$8,前提条件!$E$9))) -> 605 | D8: =D7+C8 -> 1655 | E8: =MAX(0,E7*(1-前提条件!$E$12)+C8*前提条件!$E$11-I8) -> 816.75 | F8: =F7*(1-前提条件!$E$15)+I8 -> 43.67 | G8: =E8+F8 -> 860.42 | H8: =前提条件!$E$13*MIN(1,$A8/前提条件!$E$14) -> 0.06 | I8: =E7*H8 -> 33 | J8: =F8*前提条件!$E$16 -> 30569 | K8: =IF($A8<前提条件!$E$18,0,IF($A8<=12,前提条件!$E$19,IF($A8<=24,前提条件!$E$20,前提条件!$E$21))) -> 0 | L8: =L7*(1-前提条件!$E$22)+K8 -> 0 | M8: =L8*前提条件!$E$23 -> 0 | N8: =J8+M8 -> 30569 | O8: =IF($A8<=12,前提条件!$E$25,前提条件!$E$26) -> 18000 | P8: =G8*前提条件!$E$27 -> 2581.26 | Q8: =F8*前提条件!$E$28 -> 349.36 | R8: =N8*前提条件!$E$30 -> 2445.52 | S8: =IF($A8<=12,前提条件!$E$31,IF($A8<=24,前提条件!$E$32,前提条件!$E$33)) -> 150000 | T8: =IF(F8>=前提条件!$E$34,前提条件!$E$35,0) -> 0 | U8: =IF(L8>=前提条件!$E$36,前提条件!$E$37,0) -> 0 | V8: =(O8+P8+Q8+R8+S8+T8+U8)*前提条件!$E$38 -> 17337.614 | W8: =O8+P8+Q8+R8+S8+T8+U8+V8 -> 190713.75 | X8: =N8-W8 -> -160144.75 | Y8: =Y7+X8 -> -525577.95
A9: 4 | B9: =C9/前提条件!$E$10 -> 1901.4286 | C9: =C8*(1+IF($A9<=12,前提条件!$E$7,IF($A9<=24,前提条件!$E$8,前提条件!$E$9))) -> 665.5 | D9: =D8+C9 -> 2320.5 | E9: =MAX(0,E8*(1-前提条件!$E$12)+C9*前提条件!$E$11-I9) -> 1068.43 | F9: =F8*(1-前提条件!$E$15)+I9 -> 107.6999 | G9: =E9+F9 -> 1176.1299 | H9: =前提条件!$E$13*MIN(1,$A9/前提条件!$E$14) -> 0.08 | I9: =E8*H9 -> 65.34 | J9: =F9*前提条件!$E$16 -> 75389.93 | K9: =IF($A9<前提条件!$E$18,0,IF($A9<=12,前提条件!$E$19,IF($A9<=24,前提条件!$E$20,前提条件!$E$21))) -> 1.8 | L9: =L8*(1-前提条件!$E$22)+K9 -> 1.8 | M9: =L9*前提条件!$E$23 -> 5760 | N9: =J9+M9 -> 81149.93 | O9: =IF($A9<=12,前提条件!$E$25,前提条件!$E$26) -> 18000 | P9: =G9*前提条件!$E$27 -> 3528.3897 | Q9: =F9*前提条件!$E$28 -> 861.5992 | R9: =N9*前提条件!$E$30 -> 6491.9944 | S9: =IF($A9<=12,前提条件!$E$31,IF($A9<=24,前提条件!$E$32,前提条件!$E$33)) -> 150000 | T9: =IF(F9>=前提条件!$E$34,前提条件!$E$35,0) -> 0 | U9: =IF(L9>=前提条件!$E$36,前提条件!$E$37,0) -> 0 | V9: =(O9+P9+Q9+R9+S9+T9+U9)*前提条件!$E$38 -> 17888.198 | W9: =O9+P9+Q9+R9+S9+T9+U9+V9 -> 196770.18 | X9: =N9-W9 -> -115620.25 | Y9: =Y8+X9 -> -641198.21
A10: 5 | B10: =C10/前提条件!$E$10 -> 2091.5714 | C10: =C9*(1+IF($A10<=12,前提条件!$E$7,IF($A10<=24,前提条件!$E$8,前提条件!$E$9))) -> 732.05 | D10: =D9+C10 -> 3052.55 | E10: =MAX(0,E9*(1-前提条件!$E$12)+C10*前提条件!$E$11-I10) -> 1321.4773 | F10: =F9*(1-前提条件!$E$15)+I10 -> 189.9433 | G10: =E10+F10 -> 1511.4206 | H10: =前提条件!$E$13*MIN(1,$A10/前提条件!$E$14) -> 0.08 | I10: =E9*H10 -> 85.4744 | J10: =F10*前提条件!$E$16 -> 132960.31 | K10: =IF($A10<前提条件!$E$18,0,IF($A10<=12,前提条件!$E$19,IF($A10<=24,前提条件!$E$20,前提条件!$E$21))) -> 1.8 | L10: =L9*(1-前提条件!$E$22)+K10 -> 3.564 | M10: =L10*前提条件!$E$23 -> 11404.8 | N10: =J10+M10 -> 144365.11 | O10: =IF($A10<=12,前提条件!$E$25,前提条件!$E$26) -> 18000 | P10: =G10*前提条件!$E$27 -> 4534.2618 | Q10: =F10*前提条件!$E$28 -> 1519.5464 | R10: =N10*前提条件!$E$30 -> 11549.209 | S10: =IF($A10<=12,前提条件!$E$31,IF($A10<=24,前提条件!$E$32,前提条件!$E$33)) -> 150000 | T10: =IF(F10>=前提条件!$E$34,前提条件!$E$35,0) -> 0 | U10: =IF(L10>=前提条件!$E$36,前提条件!$E$37,0) -> 0 | V10: =(O10+P10+Q10+R10+S10+T10+U10)*前提条件!$E$38 -> 18560.302 | W10: =O10+P10+Q10+R10+S10+T10+U10+V10 -> 204163.32 | X10: =N10-W10 -> -59798.207 | Y10: =Y9+X10 -> -700996.41
A11: 6 | B11: =C11/前提条件!$E$10 -> 2300.7286 | C11: =C10*(1+IF($A11<=12,前提条件!$E$7,IF($A11<=24,前提条件!$E$8,前提条件!$E$9))) -> 805.255 | D11: =D10+C11 -> 3857.805 | E11: =MAX(0,E10*(1-前提条件!$E$12)+C11*前提条件!$E$11-I11) -> 1579.3607 | F11: =F10*(1-前提条件!$E$15)+I11 -> 289.96319 | G11: =E11+F11 -> 1869.3239 | H11: =前提条件!$E$13*MIN(1,$A11/前提条件!$E$14) -> 0.08 | I11: =E10*H11 -> 105.71818 | J11: =F11*前提条件!$E$16 -> 202974.23 | K11: =IF($A11<前提条件!$E$18,0,IF($A11<=12,前提条件!$E$19,IF($A11<=24,前提条件!$E$20,前提条件!$E$21))) -> 1.8 | L11: =L10*(1-前提条件!$E$22)+K11 -> 5.29272 | M11: =L11*前提条件!$E$23 -> 16936.704 | N11: =J11+M11 -> 219910.94 | O11: =IF($A11<=12,前提条件!$E$25,前提条件!$E$26) -> 18000 | P11: =G11*前提条件!$E$27 -> 5607.9717 | Q11: =F11*前提条件!$E$28 -> 2319.7055 | R11: =N11*前提条件!$E$30 -> 17592.875 | S11: =IF($A11<=12,前提条件!$E$31,IF($A11<=24,前提条件!$E$32,前提条件!$E$33)) -> 150000 | T11: =IF(F11>=前提条件!$E$34,前提条件!$E$35,0) -> 0 | U11: =IF(L11>=前提条件!$E$36,前提条件!$E$37,0) -> 0 | V11: =(O11+P11+Q11+R11+S11+T11+U11)*前提条件!$E$38 -> 19352.055 | W11: =O11+P11+Q11+R11+S11+T11+U11+V11 -> 212872.61 | X11: =N11-W11 -> 7038.3282 | Y11: =Y10+X11 -> -693958.08
A12: 7 | B12: =C12/前提条件!$E$10 -> 2530.8014 | C12: =C11*(1+IF($A12<=12,前提条件!$E$7,IF($A12<=24,前提条件!$E$8,前提条件!$E$9))) -> 885.7805 | D12: =D11+C12 -> 4743.5855 | E12: =MAX(0,E11*(1-前提条件!$E$12)+C12*前提条件!$E$11-I12) -> 1845.4295 | F12: =F11*(1-前提条件!$E$15)+I12 -> 407.61315 | G12: =E12+F12 -> 2253.0427 | H12: =前提条件!$E$13*MIN(1,$A12/前提条件!$E$14) -> 0.08 | I12: =E11*H12 -> 126.34886 | J12: =F12*前提条件!$E$16 -> 285329.21 | K12: =IF($A12<前提条件!$E$18,0,IF($A12<=12,前提条件!$E$19,IF($A12<=24,前提条件!$E$20,前提条件!$E$21))) -> 1.8 | L12: =L11*(1-前提条件!$E$22)+K12 -> 6.9868656 | M12: =L12*前提条件!$E$23 -> 22357.97 | N12: =J12+M12 -> 307687.18 | O12: =IF($A12<=12,前提条件!$E$25,前提条件!$E$26) -> 18000 | P12: =G12*前提条件!$E$27 -> 6759.128 | Q12: =F12*前提条件!$E$28 -> 3260.9052 | R12: =N12*前提条件!$E$30 -> 24614.974 | S12: =IF($A12<=12,前提条件!$E$31,IF($A12<=24,前提条件!$E$32,前提条件!$E$33)) -> 150000 | T12: =IF(F12>=前提条件!$E$34,前提条件!$E$35,0) -> 0 | U12: =IF(L12>=前提条件!$E$36,前提条件!$E$37,0) -> 0 | V12: =(O12+P12+Q12+R12+S12+T12+U12)*前提条件!$E$38 -> 20263.501 | W12: =O12+P12+Q12+R12+S12+T12+U12+V12 -> 222898.51 | X12: =N12-W12 -> 84788.667 | Y12: =Y11+X12 -> -609169.42
A13: 8 | B13: =C13/前提条件!$E$10 -> 2783.8816 | C13: =C12*(1+IF($A13<=12,前提条件!$E$7,IF($A13<=24,前提条件!$E$8,前提条件!$E$9))) -> 974.35855 | D13: =D12+C13 -> 5717.9441 | E13: =MAX(0,E12*(1-前提条件!$E$12)+C13*前提条件!$E$11-I13) -> 2122.9666 | F13: =F12*(1-前提条件!$E$15)+I13 -> 543.01912 | G13: =E13+F13 -> 2665.9857 | H13: =前提条件!$E$13*MIN(1,$A13/前提条件!$E$14) -> 0.08 | I13: =E12*H13 -> 147.63436 | J13: =F13*前提条件!$E$16 -> 380113.38 | K13: =IF($A13<前提条件!$E$18,0,IF($A13<=12,前提条件!$E$19,IF($A13<=24,前提条件!$E$20,前提条件!$E$21))) -> 1.8 | L13: =L12*(1-前提条件!$E$22)+K13 -> 8.6471283 | M13: =L13*前提条件!$E$23 -> 27670.811 | N13: =J13+M13 -> 407784.19 | O13: =IF($A13<=12,前提条件!$E$25,前提条件!$E$26) -> 18000 | P13: =G13*前提条件!$E$27 -> 7997.9571 | Q13: =F13*前提条件!$E$28 -> 4344.1529 | R13: =N13*前提条件!$E$30 -> 32622.735 | S13: =IF($A13<=12,前提条件!$E$31,IF($A13<=24,前提条件!$E$32,前提条件!$E$33)) -> 150000 | T13: =IF(F13>=前提条件!$E$34,前提条件!$E$35,0) -> 60000 | U13: =IF(L13>=前提条件!$E$36,前提条件!$E$37,0) -> 0 | V13: =(O13+P13+Q13+R13+S13+T13+U13)*前提条件!$E$38 -> 27296.485 | W13: =O13+P13+Q13+R13+S13+T13+U13+V13 -> 300261.33 | X13: =N13-W13 -> 107522.86 | Y13: =Y12+X13 -> -501646.55
A14: 9 | B14: =C14/前提条件!$E$10 -> 3062.2697 | C14: =C13*(1+IF($A14<=12,前提条件!$E$7,IF($A14<=24,前提条件!$E$8,前提条件!$E$9))) -> 1071.7944 | D14: =D13+C14 -> 6789.7385 | E14: =MAX(0,E13*(1-前提条件!$E$12)+C14*前提条件!$E$11-I14) -> 2415.2382 | F14: =F13*(1-前提条件!$E$15)+I14 -> 696.56587 | G14: =E14+F14 -> 3111.804 | H14: =前提条件!$E$13*MIN(1,$A14/前提条件!$E$14) -> 0.08 | I14: =E13*H14 -> 169.83733 | J14: =F14*前提条件!$E$16 -> 487596.11 | K14: =IF($A14<前提条件!$E$18,0,IF($A14<=12,前提条件!$E$19,IF($A14<=24,前提条件!$E$20,前提条件!$E$21))) -> 1.8 | L14: =L13*(1-前提条件!$E$22)+K14 -> 10.274186 | M14: =L14*前提条件!$E$23 -> 32877.394 | N14: =J14+M14 -> 520473.5 | O14: =IF($A14<=12,前提条件!$E$25,前提条件!$E$26) -> 18000 | P14: =G14*前提条件!$E$27 -> 9335.4121 | Q14: =F14*前提条件!$E$28 -> 5572.5269 | R14: =N14*前提条件!$E$30 -> 41637.88 | S14: =IF($A14<=12,前提条件!$E$31,IF($A14<=24,前提条件!$E$32,前提条件!$E$33)) -> 150000 | T14: =IF(F14>=前提条件!$E$34,前提条件!$E$35,0) -> 60000 | U14: =IF(L14>=前提条件!$E$36,前提条件!$E$37,0) -> 100000 | V14: =(O14+P14+Q14+R14+S14+T14+U14)*前提条件!$E$38 -> 38454.582 | W14: =O14+P14+Q14+R14+S14+T14+U14+V14 -> 423000.4 | X14: =N14-W14 -> 97473.101 | Y14: =Y13+X14 -> -404173.45
A15: 10 | B15: =C15/前提条件!$E$10 -> 3368.4967 | C15: =C14*(1+IF($A15<=12,前提条件!$E$7,IF($A15<=24,前提条件!$E$8,前提条件!$E$9))) -> 1178.9738 | D15: =D14+C15 -> 7968.7123 | E15: =MAX(0,E14*(1-前提条件!$E$12)+C15*前提条件!$E$11-I15) -> 2725.5404 | F15: =F14*(1-前提条件!$E$15)+I15 -> 868.88795 | G15: =E15+F15 -> 3594.4284 | H15: =前提条件!$E$13*MIN(1,$A15/前提条件!$E$14) -> 0.08 | I15: =E14*H15 -> 193.21905 | J15: =F15*前提条件!$E$16 -> 608221.56 | K15: =IF($A15<前提条件!$E$18,0,IF($A15<=12,前提条件!$E$19,IF($A15<=24,前提条件!$E$20,前提条件!$E$21))) -> 1.8 | L15: =L14*(1-前提条件!$E$22)+K15 -> 11.868702 | M15: =L15*前提条件!$E$23 -> 37979.846 | N15: =J15+M15 -> 646201.41 | O15: =IF($A15<=12,前提条件!$E$25,前提条件!$E$26) -> 18000 | P15: =G15*前提条件!$E$27 -> 10783.285 | Q15: =F15*前提条件!$E$28 -> 6951.1036 | R15: =N15*前提条件!$E$30 -> 51696.113 | S15: =IF($A15<=12,前提条件!$E$31,IF($A15<=24,前提条件!$E$32,前提条件!$E$33)) -> 150000 | T15: =IF(F15>=前提条件!$E$34,前提条件!$E$35,0) -> 60000 | U15: =IF(L15>=前提条件!$E$36,前提条件!$E$37,0) -> 100000 | V15: =(O15+P15+Q15+R15+S15+T15+U15)*前提条件!$E$38 -> 39743.05 | W15: =O15+P15+Q15+R15+S15+T15+U15+V15 -> 437173.55 | X15: =N15-W15 -> 209027.86 | Y15: =Y14+X15 -> -195145.6
A16: 11 | B16: =C16/前提条件!$E$10 -> 3705.3464 | C16: =C15*(1+IF($A16<=12,前提条件!$E$7,IF($A16<=24,前提条件!$E$8,前提条件!$E$9))) -> 1296.8712 | D16: =D15+C16 -> 9265.5835 | E16: =MAX(0,E15*(1-前提条件!$E$12)+C16*前提条件!$E$11-I16) -> 3057.244 | F16: =F15*(1-前提条件!$E$15)+I16 -> 1060.8645 | G16: =E16+F16 -> 4118.1085 | H16: =前提条件!$E$13*MIN(1,$A16/前提条件!$E$14) -> 0.08 | I16: =E15*H16 -> 218.04324 | J16: =F16*前提条件!$E$16 -> 742605.18 | K16: =IF($A16<前提条件!$E$18,0,IF($A16<=12,前提条件!$E$19,IF($A16<=24,前提条件!$E$20,前提条件!$E$21))) -> 1.8 | L16: =L15*(1-前提条件!$E$22)+K16 -> 13.431328 | M16: =L16*前提条件!$E$23 -> 42980.249 | N16: =J16+M16 -> 785585.43 | O16: =IF($A16<=12,前提条件!$E$25,前提条件!$E$26) -> 18000 | P16: =G16*前提条件!$E$27 -> 12354.326 | Q16: =F16*前提条件!$E$28 -> 8486.9164 | R16: =N16*前提条件!$E$30 -> 62846.834 | S16: =IF($A16<=12,前提条件!$E$31,IF($A16<=24,前提条件!$E$32,前提条件!$E$33)) -> 150000 | T16: =IF(F16>=前提条件!$E$34,前提条件!$E$35,0) -> 60000 | U16: =IF(L16>=前提条件!$E$36,前提条件!$E$37,0) -> 100000 | V16: =(O16+P16+Q16+R16+S16+T16+U16)*前提条件!$E$38 -> 41168.808 | W16: =O16+P16+Q16+R16+S16+T16+U16+V16 -> 452856.88 | X16: =N16-W16 -> 332728.55 | Y16: =Y15+X16 -> 137582.95
A17: 12 | B17: =C17/前提条件!$E$10 -> 4075.881 | C17: =C16*(1+IF($A17<=12,前提条件!$E$7,IF($A17<=24,前提条件!$E$8,前提条件!$E$9))) -> 1426.5584 | D17: =D16+C17 -> 10692.142 | E17: =MAX(0,E16*(1-前提条件!$E$12)+C17*前提条件!$E$11-I17) -> 3413.8369 | F17: =F16*(1-前提条件!$E$15)+I17 -> 1273.6181 | G17: =E17+F17 -> 4687.455 | H17: =前提条件!$E$13*MIN(1,$A17/前提条件!$E$14) -> 0.08 | I17: =E16*H17 -> 244.57952 | J17: =F17*前提条件!$E$16 -> 891532.69 | K17: =IF($A17<前提条件!$E$18,0,IF($A17<=12,前提条件!$E$19,IF($A17<=24,前提条件!$E$20,前提条件!$E$21))) -> 1.8 | L17: =L16*(1-前提条件!$E$22)+K17 -> 14.962701 | M17: =L17*前提条件!$E$23 -> 47880.645 | N17: =J17+M17 -> 939413.33 | O17: =IF($A17<=12,前提条件!$E$25,前提条件!$E$26) -> 18000 | P17: =G17*前提条件!$E$27 -> 14062.365 | Q17: =F17*前提条件!$E$28 -> 10188.945 | R17: =N17*前提条件!$E$30 -> 75153.067 | S17: =IF($A17<=12,前提条件!$E$31,IF($A17<=24,前提条件!$E$32,前提条件!$E$33)) -> 150000 | T17: =IF(F17>=前提条件!$E$34,前提条件!$E$35,0) -> 60000 | U17: =IF(L17>=前提条件!$E$36,前提条件!$E$37,0) -> 100000 | V17: =(O17+P17+Q17+R17+S17+T17+U17)*前提条件!$E$38 -> 42740.438 | W17: =O17+P17+Q17+R17+S17+T17+U17+V17 -> 470144.81 | X17: =N17-W17 -> 469268.52 | Y17: =Y16+X17 -> 606851.47
A18: 13 | B18: =C18/前提条件!$E$10 -> 4279.6751 | C18: =C17*(1+IF($A18<=12,前提条件!$E$7,IF($A18<=24,前提条件!$E$8,前提条件!$E$9))) -> 1497.8863 | D18: =D17+C18 -> 12190.028 | E18: =MAX(0,E17*(1-前提条件!$E$12)+C18*前提条件!$E$11-I18) -> 3759.7372 | F18: =F17*(1-前提条件!$E$15)+I18 -> 1508.5165 | G18: =E18+F18 -> 5268.2537 | H18: =前提条件!$E$13*MIN(1,$A18/前提条件!$E$14) -> 0.08 | I18: =E17*H18 -> 273.10695 | J18: =F18*前提条件!$E$16 -> 1055961.6 | K18: =IF($A18<前提条件!$E$18,0,IF($A18<=12,前提条件!$E$19,IF($A18<=24,前提条件!$E$20,前提条件!$E$21))) -> 2.8 | L18: =L17*(1-前提条件!$E$22)+K18 -> 17.463447 | M18: =L18*前提条件!$E$23 -> 55883.032 | N18: =J18+M18 -> 1111844.6 | O18: =IF($A18<=12,前提条件!$E$25,前提条件!$E$26) -> 40000 | P18: =G18*前提条件!$E$27 -> 15804.761 | Q18: =F18*前提条件!$E$28 -> 12068.132 | R18: =N18*前提条件!$E$30 -> 88947.568 | S18: =IF($A18<=12,前提条件!$E$31,IF($A18<=24,前提条件!$E$32,前提条件!$E$33)) -> 200000 | T18: =IF(F18>=前提条件!$E$34,前提条件!$E$35,0) -> 60000 | U18: =IF(L18>=前提条件!$E$36,前提条件!$E$37,0) -> 100000 | V18: =(O18+P18+Q18+R18+S18+T18+U18)*前提条件!$E$38 -> 51682.046 | W18: =O18+P18+Q18+R18+S18+T18+U18+V18 -> 568502.51 | X18: =N18-W18 -> 543342.1 | Y18: =Y17+X18 -> 1150193.6
... A41: 36 | B41: =C41/前提条件!$E$10 -> 9844.1783 | C41: =C40*(1+IF($A41<=12,前提条件!$E$7,IF($A41<=24,前提条件!$E$8,前提条件!$E$9))) -> 3445.4624 | D41: =D40+C41 -> 70760.498 | E41: =MAX(0,E40*(1-前提条件!$E$12)+C41*前提条件!$E$11-I41) -> 11589.129 | F41: =F40*(1-前提条件!$E$15)+I41 -> 11540.066 | G41: =E41+F41 -> 23129.195 | H41: =前提条件!$E$13*MIN(1,$A41/前提条件!$E$14) -> 0.08 | I41: =E40*H41 -> 901.77906 | J41: =F41*前提条件!$E$16 -> 8078046.3 | K41: =IF($A41<前提条件!$E$18,0,IF($A41<=12,前提条件!$E$19,IF($A41<=24,前提条件!$E$20,前提条件!$E$21))) -> 3.8 | L41: =L40*(1-前提条件!$E$22)+K41 -> 73.768654 | M41: =L41*前提条件!$E$23 -> 236059.69 | N41: =J41+M41 -> 8314106 | O41: =IF($A41<=12,前提条件!$E$25,前提条件!$E$26) -> 40000 | P41: =G41*前提条件!$E$27 -> 69387.586 | Q41: =F41*前提条件!$E$28 -> 92320.529 | R41: =N41*前提条件!$E$30 -> 665128.48 | S41: =IF($A41<=12,前提条件!$E$31,IF($A41<=24,前提条件!$E$32,前提条件!$E$33)) -> 250000 | T41: =IF(F41>=前提条件!$E$34,前提条件!$E$35,0) -> 60000 | U41: =IF(L41>=前提条件!$E$36,前提条件!$E$37,0) -> 100000 | V41: =(O41+P41+Q41+R41+S41+T41+U41)*前提条件!$E$38 -> 127683.66 | W41: =O41+P41+Q41+R41+S41+T41+U41+V41 -> 1404520.3 | X41: =N41-W41 -> 6909585.8 | Y41: =Y40+X41 -> 80617456

Sheet サマリー比較
A1: 現場でんき探偵Pro ― サマリー比較（12/24/36ヶ月時点 × 3シナリオ）
A2: 各数値は該当シナリオシートの数式を参照。前提条件を変更すると自動更新されます。
A4: ■ 12ヶ月時点
A5: 指標 | B5: 慎重ケース | C5: 標準ケース | D5: 好調ケース
A6: 累計ダウンロード数 | B6: =慎重ケース!D17 -> 2253.8708 | C6: =標準ケース!D17 -> 5366.5354 | D6: =好調ケース!D17 -> 10692.142
A7: MAU（月間利用者数） | B7: =慎重ケース!G17 -> 623.57605 | C7: =標準ケース!G17 -> 1798.3059 | D7: =好調ケース!G17 -> 4687.455
A8: 無料利用者数 | B8: =慎重ケース!E17 -> 543.76726 | C8: =標準ケース!E17 -> 1451.2422 | D8: =好調ケース!E17 -> 3413.8369
A9: 有料利用者数（個人） | B9: =慎重ケース!F17 -> 79.80879 | C9: =標準ケース!F17 -> 347.06372 | D9: =好調ケース!F17 -> 1273.6181
A10: 当月転換率（無料→有料） | B10: =慎重ケース!H17 -> 0.03 | C10: =標準ケース!H17 -> 0.05 | D10: =好調ケース!H17 -> 0.08
A11: 個人課金売上（月額） | B11: =慎重ケース!J17 -> 43894.834 | C11: =標準ケース!J17 -> 215179.51 | D11: =好調ケース!J17 -> 891532.69
A12: 法人契約数（累計） | B12: =慎重ケース!L17 -> 1.6293166 | C12: =標準ケース!L17 -> 7.3339279 | D12: =好調ケース!L17 -> 14.962701
A13: 法人売上（月額） | B13: =慎重ケース!M17 -> 3258.6332 | C13: =標準ケース!M17 -> 19068.212 | D13: =好調ケース!M17 -> 47880.645
A14: 月間売上合計 | B14: =慎重ケース!N17 -> 47153.468 | C14: =標準ケース!N17 -> 234247.72 | D14: =好調ケース!N17 -> 939413.33
A15: 月間費用合計 | B15: =慎重ケース!W17 -> 56409.623 | C15: =標準ケース!W17 -> 134102.37 | D15: =好調ケース!W17 -> 470144.81
A16: 月次損益 | B16: =慎重ケース!X17 -> -9256.1559 | C16: =標準ケース!X17 -> 100145.35 | D16: =好調ケース!X17 -> 469268.52
A17: 累計損益 | B17: =慎重ケース!Y17 -> -424005.84 | C17: =標準ケース!Y17 -> -367141.26 | D17: =好調ケース!Y17 -> 606851.47
A18: 年間売上（1〜12ヶ月目の合計） | B18: =SUM(慎重ケース!N6:N17) -> 204983.87 | C18: =SUM(標準ケース!N6:N17) -> 1027237.1 | D18: =SUM(好調ケース!N6:N17) -> 4090840
A20: ■ 24ヶ月時点
A21: 指標 | B21: 慎重ケース | C21: 標準ケース | D21: 好調ケース
A22: 累計ダウンロード数 | B22: =慎重ケース!D29 -> 5412.9071 | C22: =標準ケース!D29 -> 15234.189 | D22: =好調ケース!D29 -> 34534.187
A23: MAU（月間利用者数） | B23: =慎重ケース!G29 -> 1117.094 | C23: =標準ケース!G29 -> 4127.1034 | D23: =好調ケース!G29 -> 12942.325
A24: 無料利用者数 | B24: =慎重ケース!E29 -> 874.43437 | C24: =標準ケース!E29 -> 2871.7635 | D24: =好調ケース!E29 -> 7635.8764
A25: 有料利用者数（個人） | B25: =慎重ケース!F29 -> 242.65962 | C25: =標準ケース!F29 -> 1255.3399 | D25: =好調ケース!F29 -> 5306.4487
A26: 当月転換率（無料→有料） | B26: =慎重ケース!H29 -> 0.03 | C26: =標準ケース!H29 -> 0.05 | D26: =好調ケース!H29 -> 0.08
A27: 個人課金売上（月額） | B27: =慎重ケース!J29 -> 133462.79 | C27: =標準ケース!J29 -> 778310.75 | D27: =好調ケース!J29 -> 3714514.1
A28: 法人契約数（累計） | B28: =慎重ケース!L29 -> 5.8394262 | C28: =標準ケース!L29 -> 22.180532 | D28: =好調ケース!L29 -> 41.881141
A29: 法人売上（月額） | B29: =慎重ケース!M29 -> 11678.852 | C29: =標準ケース!M29 -> 57669.384 | D29: =好調ケース!M29 -> 134019.65
A30: 月間売上合計 | B30: =慎重ケース!N29 -> 145141.64 | C30: =標準ケース!N29 -> 835980.14 | D30: =好調ケース!N29 -> 3848533.7
A31: 月間費用合計 | B31: =慎重ケース!W29 -> 90094.279 | C31: =標準ケース!W29 -> 384232.68 | D31: =好調ケース!W29 -> 868077.39
A32: 月次損益 | B32: =慎重ケース!X29 -> 55047.362 | C32: =標準ケース!X29 -> 451747.45 | D32: =好調ケース!X29 -> 2980456.4
A33: 累計損益 | B33: =慎重ケース!Y29 -> -245411.75 | C33: =標準ケース!Y29 -> 2103895.3 | D33: =好調ケース!Y29 -> 20556992
A34: 年間売上（13〜24ヶ月目の合計） | B34: =SUM(慎重ケース!N18:N29) -> 1194965.8 | C34: =SUM(標準ケース!N18:N29) -> 6479873.8 | D34: =SUM(好調ケース!N18:N29) -> 28426595
A36: ■ 36ヶ月時点
A37: 指標 | B37: 慎重ケース | C37: 標準ケース | D37: 好調ケース
A38: 累計ダウンロード数 | B38: =慎重ケース!D41 -> 9164.2469 | C38: =標準ケース!D41 -> 29064.741 | D38: =好調ケース!D41 -> 70760.498
A39: MAU（月間利用者数） | B39: =慎重ケース!G41 -> 1487.3406 | C39: =標準ケース!G41 -> 6578.1284 | D39: =好調ケース!G41 -> 23129.195
A40: 無料利用者数 | B40: =慎重ケース!E41 -> 1083.4604 | C40: =標準ケース!E41 -> 4108.1783 | D40: =好調ケース!E41 -> 11589.129
A41: 有料利用者数（個人） | B41: =慎重ケース!F41 -> 403.88023 | C41: =標準ケース!F41 -> 2469.9501 | D41: =好調ケース!F41 -> 11540.066
A42: 当月転換率（無料→有料） | B42: =慎重ケース!H41 -> 0.03 | C42: =標準ケース!H41 -> 0.05 | D42: =好調ケース!H41 -> 0.08
A43: 個人課金売上（月額） | B43: =慎重ケース!J41 -> 222134.13 | C43: =標準ケース!J41 -> 1531369.1 | D43: =好調ケース!J41 -> 8078046.3
...

Sheet AI費用比較
A1: AI機能の使い方による費用インパクト比較（標準ケース・36ヶ月目時点を例に）
A2: 初期版で想定する「限定AI版」（用語検索など軽量利用）と、「拡張AI版」（AIチャット相談・画像解析等を多用）を比較。
A4: 項目 | B4: 限定AI版（本編モデルの基準） | C4: 拡張AI版（参考シナリオ）
A5: 標準ケース36ヶ月目の有料会員数（個人） | B5: =標準ケース!F41 -> 2469.9501 | C5: =標準ケース!F41 -> 2469.9501
A6: AI API単価（円/有料会員/月） | B6: =前提条件!$D$28 -> 8 | C6: =前提条件!$D$29 -> 25
A7: 月間AI API費（標準ケース想定会員数） | B7: =B5*B6 -> 19759.601 | C7: =C5*C6 -> 61748.752
A8: 年間AI API費（× 12ヶ月） | B8: =B7*12 -> 237115.21 | C8: =C7*12 -> 740985.03
A10: 標準ケース36ヶ月目 月次損益（限定AI版・本編モデルどおり） | B10: =標準ケース!X41 -> 1138650.6
A11: 拡張AI版に切替えた場合の月次損益（概算） | C11: =B10-(C7-B7) -> 1096661.4
A13: ※ 拡張AI版は「限定AI版からの追加コストのみ」を月次損益から差し引いた概算です（売上への好影響は含みません）。
A14: ※ AIチャット相談などで有料転換率やARPUが向上する可能性はありますが、本シートでは費用インパクトのみを保守的に比較しています。
A15: ※ 単価は要確認（実際のAPIプロバイダー・利用量により変動）。
